Workbook
Name חודש: טבלאות!$E$2:$E$14
Name סוג_כרטיס: טבלאות!$K$2:$K$6
Name סוגי_הוצאות: טבלאות!$A$2:$A$25
Name סוגי_הכנסות: טבלאות!$C$2:$C$7

Sheet סיכום
A3: הכנסות מול הוצואות | F3: תחומי הוצאות
A5: גרף בר | F5: גרף פאי
A7: חודש בחירה | B7: אוקטובר
A9: סה"כ הכנסות | B9: =SUMIF(הכנסות!A4:G17,$B$7,הכנסות!G3:G17) -> 115
A10: סה"כ הוצאות

Sheet הכנסות
A1: הוצאות מול הכנסות
A3: חודש | B3: סוג הכנסה | G3: סה"כ הכנסות | H3: הוצאה | I3: פער
B4: משכורות | C4: צבא | D4: ביטוח לאומי | E4: ביטוח | F4: אחר
A5: ינואר | B5: =20555.96+19835.64 -> 40391.6 | C5: 220 | D5: 269 | F5: 1000 | G5: =SUM(B5:F5) -> 41880.6 | H5: =הוצאות!C78 -> 25054.09 | I5: =G5-H5 -> 16826.51
A6: פברואר | B6: =13792.62+25182.08 -> 38974.7 | C6: =422+266 -> 688 | D6: 269 | F6: 1000 | G6: =SUM(B6:F6) -> 40931.7 | H6: =הוצאות!D78 -> 56581.24 | I6: =G6-H6 -> -15649.54
A7: מרץ | B7: =33925.28+14791.47 -> 48716.75 | C7: =176+66 -> 242 | D7: 269 | F7: 1000 | G7: =SUM(B7:F7) -> 50227.75 | H7: =הוצאות!E78 -> 26671.54 | I7: =G7-H7 -> 23556.21
A8: אפריל | B8: =14111.7+19602.07 -> 33713.77 | C8: =48+22 -> 70 | D8: 269 | F8: =1000+2988 -> 3988 | G8: =SUM(B8:F8) -> 38040.77 | H8: =הוצאות!F78 -> 17018.54 | I8: =G8-H8 -> 21022.23
A9: מאי | B9: =14325.74+25804.21 -> 40129.95 | C9: =1152+6218.57+5808 -> 13178.57 | D9: 269 | F9: 1000 | G9: =SUM(B9:F9) -> 54577.52 | H9: =הוצאות!G78 -> 61784.35 | I9: =G9-H9 -> -7206.83
A10: יוני | B10: =14630.14+33927.2 -> 48557.34 | C10: =744+330 -> 1074 | D10: 115 | F10: =1430+1439+1000+3670 -> 7539 | G10: =SUM(B10:F10) -> 57285.34 | H10: =הוצאות!H78 -> 58698.5 | I10: =G10-H10 -> -1413.16
A11: יולי | B11: =16789.01+38753.59 -> 55542.6 | C11: =341+384 -> 725 | D11: 115 | F11: 1000 | G11: =SUM(B11:F11) -> 57382.6 | H11: =הוצאות!I78 -> 42550.64 | I11: =G11-H11 -> 14831.96
A12: אוגוסט | D12: 115 | G12: =SUM(B12:F12) -> 115 | H12: =הוצאות!J78 -> 4743.52 | I12: =G12-H12 -> -4628.52
A13: ספטמבר | D13: 115 | G13: =SUM(B13:F13) -> 115 | H13: =הוצאות!K78 -> 4700 | I13: =G13-H13 -> -4585
A14: אוקטובר | D14: 115 | G14: =SUM(B14:F14) -> 115 | H14: =הוצאות!L78 -> 3798.76 | I14: =G14-H14 -> -3683.76
A15: נובמבר | D15: 115 | G15: =SUM(B15:F15) -> 115 | H15: =הוצאות!M78 -> 4700 | I15: =G15-H15 -> -4585
A16: דצמבר | D16: 115 | G16: =SUM(B16:F16) -> 115 | H16: =הוצאות!N78 -> 3812.73 | I16: =G16-H16 -> -3697.73
A17: סה"כ | B17: =SUM(B5:B16) -> 306026.71 | C17: =SUM(C5:C16) -> 16197.57 | D17: =SUM(D5:D16) -> 2150 | E17: =SUM(E5:E16) -> 0 | F17: =SUM(F5:F16) -> 16527 | G17: =SUM(G5:G16) -> 340901.28 | H17: =SUM(H5:H16) -> 310113.91 | I17: =SUM(I5:I16) -> 30787.37
A19: חסכון שנתי | H19: סיכום שנתי
A21: חיסכון (מיטב/ בנק) | B21: תאריך 01.1.26 | C21: תאריך 31.12.26 | D21: פער | E21: % רווח | H21: סה"כ חיסכון שנתי | I21: =IF((C22+C23+C24)=0,0,C22-B22+C23-B23+C24-B24) -> 0
A22: מיטב דש | B22: 901372 | C22: =IF(F22=0,0,F22-הוצאות!O77) -> 0 | D22: =IF(C22>0,C22-B22,0) -> 0 | E22: =IF(C22=0,0,((C22/B22)-1)) -> 0 | H22: סה"כ הכנסות | I22: =G17 -> 340901.28
A23: בנק פקדונות | B23: 361259.51 | C23: 0 | D23: =IF(C23>0,C23-B23,0) -> 0 | E23: =IF(C23=0,0,((C23/B23)-1)) -> 0 | H23: חיסכון מההכנסות | I23: =IF(I21*I22=0,0,I21/I22) -> 0
A24: בנק שוק הון | B24: 711538.09 | C24: =IF(F24=0,0,F24-הוצאות!O75) -> 0 | D24: =IF(C24>0,C24-B24,0) -> 0 | E24: =IF(C24=0,0,((C24/B24)-1)) -> 0

Sheet הוצאות
B1: סוג הוצאה | C1: ינואר | D1: פברואר | E1: מרץ | F1: אפריל | G1: מאי | H1: יוני | I1: יולי | J1: אוגוסט | K1: ספטמבר | L1: אוקטובר | M1: נובמבר | N1: דצמבר | O1: סה"כ
A2: אשראי | B2: ביגוד והנעלה | C2: =SUMIF('1'!$L:$M,הוצאות!$B2,'1'!$M:$M) -> 0 | D2: =SUMIF('2'!$L:$M,הוצאות!$B2,'2'!$M:$M) -> 1980.4 | E2: =SUMIF('3'!$L:$M,הוצאות!$B2,'3'!$M:$M) -> 115 | F2: =SUMIF('4'!$L:$M,הוצאות!$B2,'4'!$M:$M) -> 0 | G2: =SUMIF('5'!$L:$M,הוצאות!$B2,'5'!$M:$M) -> 212.4 | H2: =SUMIF('6'!$L:$M,הוצאות!$B2,'6'!$M:$M) -> 0 | I2: =SUMIF('7'!$L:$M,הוצאות!$B2,'7'!$M:$M) -> 50 | J2: =SUMIF('8'!$L:$M,הוצאות!$B2,'8'!$M:$M) -> 0 | K2: =SUMIF('9'!$L:$M,הוצאות!$B2,'9'!$M:$M) -> 0 | L2: =SUMIF('10'!$L:$M,הוצאות!$B2,'10'!$M:$M) -> 0 | M2: =SUMIF('11'!$L:$M,הוצאות!$B2,'11'!$M:$M) -> 0 | N2: =SUMIF('12'!$L:$M,הוצאות!$B2,'12'!$M:$M) -> 0 | O2: =SUM(C2:N2) -> 2357.8
B3: ביטוח | C3: =SUMIF('1'!$L:$M,הוצאות!$B3,'1'!$M:$M) -> 553.75 | D3: =SUMIF('2'!$L:$M,הוצאות!$B3,'2'!$M:$M) -> 711.4 | E3: =SUMIF('3'!$L:$M,הוצאות!$B3,'3'!$M:$M) -> 998.23 | F3: =SUMIF('4'!$L:$M,הוצאות!$B3,'4'!$M:$M) -> 1216.34 | G3: =SUMIF('5'!$L:$M,הוצאות!$B3,'5'!$M:$M) -> 1220.08 | H3: =SUMIF('6'!$L:$M,הוצאות!$B3,'6'!$M:$M) -> 697.03 | I3: =SUMIF('7'!$L:$M,הוצאות!$B3,'7'!$M:$M) -> 732.46 | J3: =SUMIF('8'!$L:$M,הוצאות!$B3,'8'!$M:$M) -> 0 | K3: =SUMIF('9'!$L:$M,הוצאות!$B3,'9'!$M:$M) -> 0 | L3: =SUMIF('10'!$L:$M,הוצאות!$B3,'10'!$M:$M) -> 0 | M3: =SUMIF('11'!$L:$M,הוצאות!$B3,'11'!$M:$M) -> 0 | N3: =SUMIF('12'!$L:$M,הוצאות!$B3,'12'!$M:$M) -> 0 | O3: =SUM(C3:N3) -> 6129.29
B4: בילוי ומסעדות | C4: =SUMIF('1'!$L:$M,הוצאות!$B4,'1'!$M:$M) -> 70 | D4: =SUMIF('2'!$L:$M,הוצאות!$B4,'2'!$M:$M) -> 861 | E4: =SUMIF('3'!$L:$M,הוצאות!$B4,'3'!$M:$M) -> 272 | F4: =SUMIF('4'!$L:$M,הוצאות!$B4,'4'!$M:$M) -> 49 | G4: =SUMIF('5'!$L:$M,הוצאות!$B4,'5'!$M:$M) -> 0 | H4: =SUMIF('6'!$L:$M,הוצאות!$B4,'6'!$M:$M) -> 1135 | I4: =SUMIF('7'!$L:$M,הוצאות!$B4,'7'!$M:$M) -> 141.4 | J4: =SUMIF('8'!$L:$M,הוצאות!$B4,'8'!$M:$M) -> 0 | K4: =SUMIF('9'!$L:$M,הוצאות!$B4,'9'!$M:$M) -> 0 | L4: =SUMIF('10'!$L:$M,הוצאות!$B4,'10'!$M:$M) -> 0 | M4: =SUMIF('11'!$L:$M,הוצאות!$B4,'11'!$M:$M) -> 0 | N4: =SUMIF('12'!$L:$M,הוצאות!$B4,'12'!$M:$M) -> 0 | O4: =SUM(C4:N4) -> 2528.4
B5: בית וגן | C5: =SUMIF('1'!$L:$M,הוצאות!$B5,'1'!$M:$M) -> 946.49 | D5: =SUMIF('2'!$L:$M,הוצאות!$B5,'2'!$M:$M) -> 622.36 | E5: =SUMIF('3'!$L:$M,הוצאות!$B5,'3'!$M:$M) -> 1053.62 | F5: =SUMIF('4'!$L:$M,הוצאות!$B5,'4'!$M:$M) -> 524.32 | G5: =SUMIF('5'!$L:$M,הוצאות!$B5,'5'!$M:$M) -> 486.5 | H5: =SUMIF('6'!$L:$M,הוצאות!$B5,'6'!$M:$M) -> 603.36 | I5: =SUMIF('7'!$L:$M,הוצאות!$B5,'7'!$M:$M) -> 997.33 | J5: =SUMIF('8'!$L:$M,הוצאות!$B5,'8'!$M:$M) -> 0 | K5: =SUMIF('9'!$L:$M,הוצאות!$B5,'9'!$M:$M) -> 0 | L5: =SUMIF('10'!$L:$M,הוצאות!$B5,'10'!$M:$M) -> 0 | M5: =SUMIF('11'!$L:$M,הוצאות!$B5,'11'!$M:$M) -> 0 | N5: =SUMIF('12'!$L:$M,הוצאות!$B5,'12'!$M:$M) -> 0 | O5: =SUM(C5:N5) -> 5233.98
B6: בית ספר | C6: =SUMIF('1'!$L:$M,הוצאות!$B6,'1'!$M:$M) -> 750 | D6: =SUMIF('2'!$L:$M,הוצאות!$B6,'2'!$M:$M) -> 746 | E6: =SUMIF('3'!$L:$M,הוצאות!$B6,'3'!$M:$M) -> 746 | F6: =SUMIF('4'!$L:$M,הוצאות!$B6,'4'!$M:$M) -> 746 | G6: =SUMIF('5'!$L:$M,הוצאות!$B6,'5'!$M:$M) -> 0 | H6: =SUMIF('6'!$L:$M,הוצאות!$B6,'6'!$M:$M) -> 0 | I6: =SUMIF('7'!$L:$M,הוצאות!$B6,'7'!$M:$M) -> 0 | J6: =SUMIF('8'!$L:$M,הוצאות!$B6,'8'!$M:$M) -> 0 | K6: =SUMIF('9'!$L:$M,הוצאות!$B6,'9'!$M:$M) -> 0 | L6: =SUMIF('10'!$L:$M,הוצאות!$B6,'10'!$M:$M) -> 0 | M6: =SUMIF('11'!$L:$M,הוצאות!$B6,'11'!$M:$M) -> 0 | N6: =SUMIF('12'!$L:$M,הוצאות!$B6,'12'!$M:$M) -> 0 | O6: =SUM(C6:N6) -> 2988
B7: בריאות | C7: =SUMIF('1'!$L:$M,הוצאות!$B7,'1'!$M:$M) -> 413.41 | D7: =SUMIF('2'!$L:$M,הוצאות!$B7,'2'!$M:$M) -> 862.43 | E7: =SUMIF('3'!$L:$M,הוצאות!$B7,'3'!$M:$M) -> 674.51 | F7: =SUMIF('4'!$L:$M,הוצאות!$B7,'4'!$M:$M) -> 549.65 | G7: =SUMIF('5'!$L:$M,הוצאות!$B7,'5'!$M:$M) -> 265.42 | H7: =SUMIF('6'!$L:$M,הוצאות!$B7,'6'!$M:$M) -> 1641.86 | I7: =SUMIF('7'!$L:$M,הוצאות!$B7,'7'!$M:$M) -> 493.64 | J7: =SUMIF('8'!$L:$M,הוצאות!$B7,'8'!$M:$M) -> 0 | K7: =SUMIF('9'!$L:$M,הוצאות!$B7,'9'!$M:$M) -> 0 | L7: =SUMIF('10'!$L:$M,הוצאות!$B7,'10'!$M:$M) -> 0 | M7: =SUMIF('11'!$L:$M,הוצאות!$B7,'11'!$M:$M) -> 0 | N7: =SUMIF('12'!$L:$M,הוצאות!$B7,'12'!$M:$M) -> 0 | O7: =SUM(C7:N7) -> 4900.92
B8: הלוואות ומשכנתא | C8: =SUMIF('1'!$L:$M,הוצאות!$B8,'1'!$M:$M) -> 0 | D8: =SUMIF('2'!$L:$M,הוצאות!$B8,'2'!$M:$M) -> 0 | E8: =SUMIF('3'!$L:$M,הוצאות!$B8,'3'!$M:$M) -> 0 | F8: =SUMIF('4'!$L:$M,הוצאות!$B8,'4'!$M:$M) -> 0 | G8: =SUMIF('5'!$L:$M,הוצאות!$B8,'5'!$M:$M) -> 0 | H8: =SUMIF('6'!$L:$M,הוצאות!$B8,'6'!$M:$M) -> 0 | I8: =SUMIF('7'!$L:$M,הוצאות!$B8,'7'!$M:$M) -> 0 | J8: =SUMIF('8'!$L:$M,הוצאות!$B8,'8'!$M:$M) -> 0 | K8: =SUMIF('9'!$L:$M,הוצאות!$B8,'9'!$M:$M) -> 0 | L8: =SUMIF('10'!$L:$M,הוצאות!$B8,'10'!$M:$M) -> 0 | M8: =SUMIF('11'!$L:$M,הוצאות!$B8,'11'!$M:$M) -> 0 | N8: =SUMIF('12'!$L:$M,הוצאות!$B8,'12'!$M:$M) -> 0 | O8: =SUM(C8:N8) -> 0
B9: חוגים | C9: =SUMIF('1'!$L:$M,הוצאות!$B9,'1'!$M:$M) -> 1655 | D9: =SUMIF('2'!$L:$M,הוצאות!$B9,'2'!$M:$M) -> 1975 | E9: =SUMIF('3'!$L:$M,הוצאות!$B9,'3'!$M:$M) -> 2665 | F9: =SUMIF('4'!$L:$M,הוצאות!$B9,'4'!$M:$M) -> 880 | G9: =SUMIF('5'!$L:$M,הוצאות!$B9,'5'!$M:$M) -> 8891 | H9: =SUMIF('6'!$L:$M,הוצאות!$B9,'6'!$M:$M) -> 1310 | I9: =SUMIF('7'!$L:$M,הוצאות!$B9,'7'!$M:$M) -> 870 | J9: =SUMIF('8'!$L:$M,הוצאות!$B9,'8'!$M:$M) -> 0 | K9: =SUMIF('9'!$L:$M,הוצאות!$B9,'9'!$M:$M) -> 0 | L9: =SUMIF('10'!$L:$M,הוצאות!$B9,'10'!$M:$M) -> 0 | M9: =SUMIF('11'!$L:$M,הוצאות!$B9,'11'!$M:$M) -> 0 | N9: =SUMIF('12'!$L:$M,הוצאות!$B9,'12'!$M:$M) -> 0 | O9: =SUM(C9:N9) -> 18246
B10: חינוך ומשפחה | C10: =SUMIF('1'!$L:$M,הוצאות!$B10,'1'!$M:$M) -> 0 | D10: =SUMIF('2'!$L:$M,הוצאות!$B10,'2'!$M:$M) -> 5250 | E10: =SUMIF('3'!$L:$M,הוצאות!$B10,'3'!$M:$M) -> 5250 | F10: =SUMIF('4'!$L:$M,הוצאות!$B10,'4'!$M:$M) -> 0 | G10: =SUMIF('5'!$L:$M,הוצאות!$B10,'5'!$M:$M) -> 0 | H10: =SUMIF('6'!$L:$M,הוצאות!$B10,'6'!$M:$M) -> 0 | I10: =SUMIF('7'!$L:$M,הוצאות!$B10,'7'!$M:$M) -> 0 | J10: =SUMIF('8'!$L:$M,הוצאות!$B10,'8'!$M:$M) -> 0 | K10: =SUMIF('9'!$L:$M,הוצאות!$B10,'9'!$M:$M) -> 0 | L10: =SUMIF('10'!$L:$M,הוצאות!$B10,'10'!$M:$M) -> 0 | M10: =SUMIF('11'!$L:$M,הוצאות!$B10,'11'!$M:$M) -> 0 | N10: =SUMIF('12'!$L:$M,הוצאות!$B10,'12'!$M:$M) -> 0 | O10: =SUM(C10:N10) -> 10500
B11: חיסכון | C11: =SUMIF('1'!$L:$M,הוצאות!$B11,'1'!$M:$M) -> 0 | D11: =SUMIF('2'!$L:$M,הוצאות!$B11,'2'!$M:$M) -> 0 | E11: =SUMIF('3'!$L:$M,הוצאות!$B11,'3'!$M:$M) -> 0 | F11: =SUMIF('4'!$L:$M,הוצאות!$B11,'4'!$M:$M) -> 0 | G11: =SUMIF('5'!$L:$M,הוצאות!$B11,'5'!$M:$M) -> 0 | H11: =SUMIF('6'!$L:$M,הוצאות!$B11,'6'!$M:$M) -> 0 | I11: =SUMIF('7'!$L:$M,הוצאות!$B11,'7'!$M:$M) -> 0 | J11: =SUMIF('8'!$L:$M,הוצאות!$B11,'8'!$M:$M) -> 0 | K11: =SUMIF('9'!$L:$M,הוצאות!$B11,'9'!$M:$M) -> 0 | L11: =SUMIF('10'!$L:$M,הוצאות!$B11,'10'!$M:$M) -> 0 | M11: =SUMIF('11'!$L:$M,הוצאות!$B11,'11'!$M:$M) -> 0 | N11: =SUMIF('12'!$L:$M,הוצאות!$B11,'12'!$M:$M) -> 0 | O11: =SUM(C11:N11) -> 0
B12: ילדים | C12: =SUMIF('1'!$L:$M,הוצאות!$B12,'1'!$M:$M) -> 0 | D12: =SUMIF('2'!$L:$M,הוצאות!$B12,'2'!$M:$M) -> 0 | E12: =SUMIF('3'!$L:$M,הוצאות!$B12,'3'!$M:$M) -> 658.77 | F12: =SUMIF('4'!$L:$M,הוצאות!$B12,'4'!$M:$M) -> 65 | G12: =SUMIF('5'!$L:$M,הוצאות!$B12,'5'!$M:$M) -> 1169.9 | H12: =SUMIF('6'!$L:$M,הוצאות!$B12,'6'!$M:$M) -> 799.9 | I12: =SUMIF('7'!$L:$M,הוצאות!$B12,'7'!$M:$M) -> 210 | J12: =SUMIF('8'!$L:$M,הוצאות!$B12,'8'!$M:$M) -> 0 | K12: =SUMIF('9'!$L:$M,הוצאות!$B12,'9'!$M:$M) -> 0 | L12: =SUMIF('10'!$L:$M,הוצאות!$B12,'10'!$M:$M) -> 0 | M12: =SUMIF('11'!$L:$M,הוצאות!$B12,'11'!$M:$M) -> 0 | N12: =SUMIF('12'!$L:$M,הוצאות!$B12,'12'!$M:$M) -> 0 | O12: =SUM(C12:N12) -> 2903.57
B13: מוצרי חשמל ותקשורת | C13: =SUMIF('1'!$L:$M,הוצאות!$B13,'1'!$M:$M) -> 1660.77 | D13: =SUMIF('2'!$L:$M,הוצאות!$B13,'2'!$M:$M) -> 392.1 | E13: =SUMIF('3'!$L:$M,הוצאות!$B13,'3'!$M:$M) -> 1527.46 | F13: =SUMIF('4'!$L:$M,הוצאות!$B13,'4'!$M:$M) -> 566.44 | G13: =SUMIF('5'!$L:$M,הוצאות!$B13,'5'!$M:$M) -> 404.12 | H13: =SUMIF('6'!$L:$M,הוצאות!$B13,'6'!$M:$M) -> 1671.3 | I13: =SUMIF('7'!$L:$M,הוצאות!$B13,'7'!$M:$M) -> 1003.93 | J13: =SUMIF('8'!$L:$M,הוצאות!$B13,'8'!$M:$M) -> 0 | K13: =SUMIF('9'!$L:$M,הוצאות!$B13,'9'!$M:$M) -> 0 | L13: =SUMIF('10'!$L:$M,הוצאות!$B13,'10'!$M:$M) -> 0 | M13: =SUMIF('11'!$L:$M,הוצאות!$B13,'11'!$M:$M) -> 0 | N13: =SUMIF('12'!$L:$M,הוצאות!$B13,'12'!$M:$M) -> 0 | O13: =SUM(C13:N13) -> 7226.12
B14: מזומן | C14: =SUMIF('1'!$L:$M,הוצאות!$B14,'1'!$M:$M) -> 0 | D14: =SUMIF('2'!$L:$M,הוצאות!$B14,'2'!$M:$M) -> 0 | E14: =SUMIF('3'!$L:$M,הוצאות!$B14,'3'!$M:$M) -> 0 | F14: =SUMIF('4'!$L:$M,הוצאות!$B14,'4'!$M:$M) -> 0 | G14: =SUMIF('5'!$L:$M,הוצאות!$B14,'5'!$M:$M) -> 0 | H14: =SUMIF('6'!$L:$M,הוצאות!$B14,'6'!$M:$M) -> 0 | I14: =SUMIF('7'!$L:$M,הוצאות!$B14,'7'!$M:$M) -> 0 | J14: =SUMIF('8'!$L:$M,הוצאות!$B14,'8'!$M:$M) -> 0 | K14: =SUMIF('9'!$L:$M,הוצאות!$B14,'9'!$M:$M) -> 0 | L14: =SUMIF('10'!$L:$M,הוצאות!$B14,'10'!$M:$M) -> 0 | M14: =SUMIF('11'!$L:$M,הוצאות!$B14,'11'!$M:$M) -> 0 | N14: =SUMIF('12'!$L:$M,הוצאות!$B14,'12'!$M:$M) -> 0 | O14: =SUM(C14:N14) -> 0
... B25: חיסכון (מיטב) | C25: =SUMIF('1'!$L:$M,הוצאות!$B25,'1'!$M:$M) -> 0 | D25: =SUMIF('2'!$L:$M,הוצאות!$B25,'2'!$M:$M) -> 0 | E25: =SUMIF('3'!$L:$M,הוצאות!$B25,'3'!$M:$M) -> 0 | F25: =SUMIF('4'!$L:$M,הוצאות!$B25,'4'!$M:$M) -> 0 | G25: =SUMIF('5'!$L:$M,הוצאות!$B25,'5'!$M:$M) -> 0 | H25: =SUMIF('6'!$L:$M,הוצאות!$B25,'6'!$M:$M) -> 0 | I25: =SUMIF('7'!$L:$M,הוצאות!$B25,'7'!$M:$M) -> 0 | J25: =SUMIF('8'!$L:$M,הוצאות!$B25,'8'!$M:$M) -> 0 | K25: =SUMIF('9'!$L:$M,הוצאות!$B25,'9'!$M:$M) -> 0 | L25: =SUMIF('10'!$L:$M,הוצאות!$B25,'10'!$M:$M) -> 0 | M25: =SUMIF('11'!$L:$M,הוצאות!$B25,'11'!$M:$M) -> 0 | N25: =SUMIF('12'!$L:$M,הוצאות!$B25,'12'!$M:$M) -> 0 | O25: =SUM(C25:N25) -> 0
B26: סה"כ אשראי | C26: =SUM(C2:C25) -> 22053.24 | D26: =SUM(D2:D25) -> 29652.09 | E26: =SUM(E2:E25) -> 23081.43 | F26: =SUM(F2:F25) -> 12148.5 | G26: =SUM(G2:G25) -> 18777.92 | H26: =SUM(H2:H25) -> 33935.07 | I26: =SUM(I2:I25) -> 16501.6 | J26: =SUM(J2:J25) -> 0 | ... N26: =SUM(N2:N25) -> 0 | O26: =SUM(C26:N26) -> 156149.85
A27: ידני | B27: ביגוד והנעלה | C27: ='הוצאות ידני'!B3 -> 0 | D27: ='הוצאות ידני'!C3 -> 0 | E27: ='הוצאות ידני'!D3 -> 0 | F27: ='הוצאות ידני'!E3 -> 0 | G27: ='הוצאות ידני'!F3 -> 0 | H27: ='הוצאות ידני'!G3 -> 0 | I27: ='הוצאות ידני'!H3 -> 0 | J27: ='הוצאות ידני'!I3 -> 0 | ... N27: ='הוצאות ידני'!M3 -> 0 | O27: =SUM(C27:N27) -> 0
B28: ביטוח | C28: ='הוצאות ידני'!B4 -> 0 | D28: ='הוצאות ידני'!C4 -> 0 | E28: ='הוצאות ידני'!D4 -> 0 | F28: ='הוצאות ידני'!E4 -> 0 | G28: ='הוצאות ידני'!F4 -> 0 | H28: ='הוצאות ידני'!G4 -> 0 | I28: ='הוצאות ידני'!H4 -> 0 | J28: ='הוצאות ידני'!I4 -> 0 | ... N28: ='הוצאות ידני'!M4 -> 0 | O28: =SUM(C28:N28) -> 0
B29: בילוי ומסעדות | C29: ='הוצאות ידני'!B5 -> 0 | D29: ='הוצאות ידני'!C5 -> 0 | E29: ='הוצאות ידני'!D5 -> 0 | F29: ='הוצאות ידני'!E5 -> 0 | G29: ='הוצאות ידני'!F5 -> 0 | H29: ='הוצאות ידני'!G5 -> 0 | I29: ='הוצאות ידני'!H5 -> 0 | J29: ='הוצאות ידני'!I5 -> 0 | ... N29: ='הוצאות ידני'!M5 -> 0 | O29: =SUM(C29:N29) -> 0
B30: בית וגן | C30: ='הוצאות ידני'!B6 -> 0 | D30: ='הוצאות ידני'!C6 -> 1907.83 | E30: ='הוצאות ידני'!D6 -> 0 | F30: ='הוצאות ידני'!E6 -> 1867.3 | G30: ='הוצאות ידני'!F6 -> 0 | H30: ='הוצאות ידני'!G6 -> 1763.43 | I30: ='הוצאות ידני'!H6 -> 0 | J30: ='הוצאות ידני'!I6 -> 1942.67 | ... N30: ='הוצאות ידני'!M6 -> 1962.73 | O30: =SUM(C30:N30) -> 11391.87
B31: בית ספר | C31: ='הוצאות ידני'!B7 -> 0 | D31: ='הוצאות ידני'!C7 -> 0 | E31: ='הוצאות ידני'!D7 -> 0 | F31: ='הוצאות ידני'!E7 -> 0 | G31: ='הוצאות ידני'!F7 -> 0 | H31: ='הוצאות ידני'!G7 -> 0 | I31: ='הוצאות ידני'!H7 -> 0 | J31: ='הוצאות ידני'!I7 -> 0 | ... N31: ='הוצאות ידני'!M7 -> 0 | O31: =SUM(C31:N31) -> 0
B32: בריאות | C32: ='הוצאות ידני'!B8 -> 0 | D32: ='הוצאות ידני'!C8 -> 0 | E32: ='הוצאות ידני'!D8 -> 0 | F32: ='הוצאות ידני'!E8 -> 0 | G32: ='הוצאות ידני'!F8 -> 0 | H32: ='הוצאות ידני'!G8 -> 0 | I32: ='הוצאות ידני'!H8 -> 0 | J32: ='הוצאות ידני'!I8 -> 0 | ... N32: ='הוצאות ידני'!M8 -> 0 | O32: =SUM(C32:N32) -> 0
B33: הלוואות ומשכנתא | C33: ='הוצאות ידני'!B9 -> 0 | D33: ='הוצאות ידני'!C9 -> 0 | E33: ='הוצאות ידני'!D9 -> 565 | F33: ='הוצאות ידני'!E9 -> 0 | G33: ='הוצאות ידני'!F9 -> 0 | H33: ='הוצאות ידני'!G9 -> 0 | I33: ='הוצאות ידני'!H9 -> 0 | J33: ='הוצאות ידני'!I9 -> 0 | ... N33: ='הוצאות ידני'!M9 -> 0 | O33: =SUM(C33:N33) -> 565
B34: חוגים | C34: ='הוצאות ידני'!B10 -> 200 | D34: ='הוצאות ידני'!C10 -> 200 | E34: ='הוצאות ידני'!D10 -> 200 | F34: ='הוצאות ידני'!E10 -> 200 | G34: ='הוצאות ידני'!F10 -> 200 | H34: ='הוצאות ידני'!G10 -> 200 | I34: ='הוצאות ידני'!H10 -> 200 | J34: ='הוצאות ידני'!I10 -> 0 | ... N34: ='הוצאות ידני'!M10 -> 200 | O34: =SUM(C34:N34) -> 2200
B35: חינוך ומשפחה | C35: ='הוצאות ידני'!B11 -> 0 | D35: ='הוצאות ידני'!C11 -> 0 | E35: ='הוצאות ידני'!D11 -> 0 | F35: ='הוצאות ידני'!E11 -> 0 | G35: ='הוצאות ידני'!F11 -> 0 | H35: ='הוצאות ידני'!G11 -> 0 | I35: ='הוצאות ידני'!H11 -> 0 | J35: ='הוצאות ידני'!I11 -> 0 | ... N35: ='הוצאות ידני'!M11 -> 0 | O35: =SUM(C35:N35) -> 0
B36: חיסכון | C36: ='הוצאות ידני'!B12 -> 1650.85 | D36: ='הוצאות ידני'!C12 -> 1671.32 | E36: ='הוצאות ידני'!D12 -> 1675.11 | F36: ='הוצאות ידני'!E12 -> 1652.74 | G36: ='הוצאות ידני'!F12 -> 1656.43 | H36: ='הוצאות ידני'!G12 -> 1650 | I36: ='הוצאות ידני'!H12 -> 1699.04 | J36: ='הוצאות ידני'!I12 -> 1650.85 | ... N36: ='הוצאות ידני'!M12 -> 1650 | O36: =SUM(C36:N36) -> 19907.19
B37: ילדים | C37: ='הוצאות ידני'!B13 -> 0 | D37: ='הוצאות ידני'!C13 -> 0 | E37: ='הוצאות ידני'!D13 -> 0 | F37: ='הוצאות ידני'!E13 -> 0 | G37: ='הוצאות ידני'!F13 -> 0 | H37: ='הוצאות ידני'!G13 -> 0 | I37: ='הוצאות ידני'!H13 -> 0 | J37: ='הוצאות ידני'!I13 -> 0 | ... N37: ='הוצאות ידני'!M13 -> 0 | O37: =SUM(C37:N37) -> 0
B38: מוצרי חשמל ותקשורת | C38: ='הוצאות ידני'!B14 -> 0 | D38: ='הוצאות ידני'!C14 -> 0 | E38: ='הוצאות ידני'!D14 -> 0 | F38: ='הוצאות ידני'!E14 -> 0 | G38: ='הוצאות ידני'!F14 -> 0 | H38: ='הוצאות ידני'!G14 -> 0 | I38: ='הוצאות ידני'!H14 -> 0 | J38: ='הוצאות ידני'!I14 -> 0 | ... N38: ='הוצאות ידני'!M14 -> 0 | O38: =SUM(C38:N38) -> 0
B39: מזומן | C39: ='הוצאות ידני'!B15 -> 0 | D39: ='הוצאות ידני'!C15 -> 0 | E39: ='הוצאות ידני'!D15 -> 0 | F39: ='הוצאות ידני'!E15 -> 0 | G39: ='הוצאות ידני'!F15 -> 0 | H39: ='הוצאות ידני'!G15 -> 0 | I39: ='הוצאות ידני'!H15 -> 0 | J39: ='הוצאות ידני'!I15 -> 0 | ... N39: ='הוצאות ידני'!M15 -> 0 | O39: =SUM(C39:N39) -> 0
... B42: מתנות ומזכרות | C42: ='הוצאות ידני'!B18 -> 0 | D42: ='הוצאות ידני'!C18 -> 0 | E42: ='הוצאות ידני'!D18 -> 0 | F42: ='הוצאות ידני'!E18 -> 0 | G42: ='הוצאות ידני'!F18 -> 0 | H42: ='הוצאות ידני'!G18 -> 0 | I42: ='הוצאות ידני'!H18 -> 0 | J42: ='הוצאות ידני'!I18 -> 0 | ... N42: ='הוצאות ידני'!M18 -> 0 | O42: =SUM(C42:N42) -> 0
B43: נופש | C43: ='הוצאות ידני'!B2 -> 0 | D43: ='הוצאות ידני'!C2 -> 0 | E43: ='הוצאות ידני'!D2 -> 0 | F43: ='הוצאות ידני'!E2 -> 0 | G43: ='הוצאות ידני'!F2 -> 0 | H43: ='הוצאות ידני'!G2 -> 0 | I43: ='הוצאות ידני'!H2 -> 0 | J43: ='הוצאות ידני'!I2 -> 0 | ... N43: ='הוצאות ידני'!M2 -> 0 | O43: =SUM(C43:N43) -> 0
B44: קניית דירה/ שכירות | C44: ='הוצאות ידני'!B19 -> 0 | D44: ='הוצאות ידני'!C19 -> 0 | E44: ='הוצאות ידני'!D19 -> 0 | F44: ='הוצאות ידני'!E19 -> 0 | G44: ='הוצאות ידני'!F19 -> 0 | H44: ='הוצאות ידני'!G19 -> 0 | I44: ='הוצאות ידני'!H19 -> 0 | J44: ='הוצאות ידני'!I19 -> 0 | ... N44: ='הוצאות ידני'!M19 -> 0 | O44: =SUM(C44:N44) -> 0
B45: רכב ותחבורה | C45: ='הוצאות ידני'!B20 -> 0 | D45: ='הוצאות ידני'!C20 -> 0 | E45: ='הוצאות ידני'!D20 -> 0 | F45: ='הוצאות ידני'!E20 -> 0 | G45: ='הוצאות ידני'!F20 -> 0 | H45: ='הוצאות ידני'!G20 -> 0 | I45: ='הוצאות ידני'!H20 -> 0 | J45: ='הוצאות ידני'!I20 -> 0 | ... N45: ='הוצאות ידני'!M20 -> 0 | O45: =SUM(C45:N45) -> 0
B46: שונות | C46: ='הוצאות ידני'!B21 -> 0 | D46: ='הוצאות ידני'!C21 -> 0 | E46: ='הוצאות ידני'!D21 -> 0 | F46: ='הוצאות ידני'!E21 -> 0 | G46: ='הוצאות ידני'!F21 -> 0 | H46: ='הוצאות ידני'!G21 -> 0 | I46: ='הוצאות ידני'!H21 -> 0 | J46: ='הוצאות ידני'!I21 -> 0 | ... N46: ='הוצאות ידני'!M21 -> 0 | O46: =SUM(C46:N46) -> 0
B47: שירותי בנקאות | C47: ='הוצאות ידני'!B22 -> 0 | D47: ='הוצאות ידני'!C22 -> 0 | E47: ='הוצאות ידני'!D22 -> 0 | F47: ='הוצאות ידני'!E22 -> 0 | G47: ='הוצאות ידני'!F22 -> 0 | H47: ='הוצאות ידני'!G22 -> 0 | I47: ='הוצאות ידני'!H22 -> 0 | J47: ='הוצאות ידני'!I22 -> 0 | ... N47: ='הוצאות ידני'!M22 -> 0 | O47: =SUM(C47:N47) -> 0
B48: תרבות ופנאי | C48: ='הוצאות ידני'!B23 -> 0 | D48: ='הוצאות ידני'!C23 -> 0 | E48: ='הוצאות ידני'!D23 -> 0 | F48: ='הוצאות ידני'!E23 -> 0 | G48: ='הוצאות ידני'!F23 -> 0 | H48: ='הוצאות ידני'!G23 -> 0 | I48: ='הוצאות ידני'!H23 -> 0 | J48: ='הוצאות ידני'!I23 -> 0 | ... N48: ='הוצאות ידני'!M23 -> 0 | O48: =SUM(C48:N48) -> 0
B49: השקעות (בנק) | C49: ='הוצאות ידני'!B24 -> 0 | D49: ='הוצאות ידני'!C24 -> 22000 | E49: ='הוצאות ידני'!D24 -> 0 | F49: ='הוצאות ידני'!E24 -> 0 | G49: ='הוצאות ידני'!F24 -> 40000 | H49: ='הוצאות ידני'!G24 -> 15000 | I49: ='הוצאות ידני'!H24 -> 23000 | J49: ='הוצאות ידני'!I24 -> 0 | ... N49: ='הוצאות ידני'!M24 -> 0 | O49: =SUM(C49:N49) -> 100000
B50: חיסכון (בנק) | C50: ='הוצאות ידני'!B25 -> 0 | D50: ='הוצאות ידני'!C25 -> 0 | E50: ='הוצאות ידני'!D25 -> 0 | F50: ='הוצאות ידני'!E25 -> 0 | G50: ='הוצאות ידני'!F25 -> 0 | H50: ='הוצאות ידני'!G25 -> 0 | I50: ='הוצאות ידני'!H25 -> 0 | J50: ='הוצאות ידני'!I25 -> 0 | ... N50: ='הוצאות ידני'!M25 -> 0 | O50: =SUM(C50:N50) -> 0
B51: חיסכון (מיטב) | C51: ='הוצאות ידני'!B26 -> 0 | D51: ='הוצאות ידני'!C26 -> 0 | E51: ='הוצאות ידני'!D26 -> 0 | F51: ='הוצאות ידני'!E26 -> 0 | G51: ='הוצאות ידני'!F26 -> 0 | H51: ='הוצאות ידני'!G26 -> 5000 | I51: ='הוצאות ידני'!H26 -> 0 | J51: ='הוצאות ידני'!I26 -> 0 | ... N51: ='הוצאות ידני'!M26 -> 0 | O51: =SUM(C51:N51) -> 5000
B52: סה"כ ידני | C52: =SUM(C27:C51) -> 3000.85 | D52: =SUM(D27:D51) -> 26929.15 | E52: =SUM(E27:E51) -> 3590.11 | F52: =SUM(F27:F51) -> 4870.04 | G52: =SUM(G27:G51) -> 43006.43 | H52: =SUM(H27:H51) -> 24763.43 | I52: =SUM(I27:I51) -> 26049.04 | J52: =SUM(J27:J51) -> 4743.52 | ... N52: =SUM(N27:N51) -> 3812.73 | O52: =SUM(C52:N52) -> 153964.06
...

Sheet הוצאות ידני
A1: סוג הוצאה | B1: ינואר | C1: פברואר | D1: מרץ | E1: אפריל | F1: מאי | G1: יוני | H1: יולי | I1: אוגוסט | J1: ספטמבר | K1: אוקטובר | L1: נובמבר | M1: דצמבר | N1: סה"כ
A2: נופש | N2: =SUM(B2:M2) -> 0
A3: ביגוד והנעלה | N3: =SUM(B3:M3) -> 0
A4: ביטוח | N4: =SUM(B4:M4) -> 0
A5: בילוי ומסעדות | N5: =SUM(B5:M5) -> 0
A6: בית וגן | C6: =1715.1+192.73 -> 1907.83 | E6: =1707.1+160.2 -> 1867.3 | G6: =1602.9+160.53 -> 1763.43 | I6: =1711.2+231.47 -> 1942.67 | K6: =1711.2+236.71 -> 1947.91 | M6: =1728.6+234.13 -> 1962.73 | N6: =SUM(B6:M6) -> 11391.87
A7: בית ספר | N7: =SUM(B7:M7) -> 0
A8: בריאות | N8: =SUM(B8:M8) -> 0
A9: הלוואות ומשכנתא | D9: 565 | N9: =SUM(B9:M9) -> 565
A10: חוגים | B10: =200 -> 200 | C10: =200 -> 200 | D10: =200 -> 200 | E10: =200 -> 200 | F10: =200 -> 200 | G10: =200 -> 200 | H10: =200 -> 200 | J10: =200 -> 200 | K10: =200 -> 200 | L10: =200 -> 200 | M10: =200 -> 200 | N10: =SUM(B10:M10) -> 2200
A11: חינוך ומשפחה | N11: =SUM(B11:M11) -> 0
A12: חיסכון | B12: =650.85+1000 -> 1650.85 | C12: =671.32+1000 -> 1671.32 | D12: =675.11+1000 -> 1675.11 | E12: =652.74+1000 -> 1652.74 | F12: =656.43+1000 -> 1656.43 | G12: =650+1000 -> 1650 | H12: =699.04+1000 -> 1699.04 | I12: =650.85+1000 -> 1650.85 | J12: =650+1000 -> 1650 | K12: =650.85+1000 -> 1650.85 | L12: =650+1000 -> 1650 | M12: =650+1000 -> 1650 | N12: =SUM(B12:M12) -> 19907.19
A13: ילדים | N13: =SUM(B13:M13) -> 0
A14: מוצרי חשמל ותקשורת | N14: =SUM(B14:M14) -> 0
A15: מזומן | N15: =SUM(B15:M15) -> 0
A16: מזון ומשקאות | N16: =SUM(B16:M16) -> 0
A17: שכירות דירה | B17: 1150 | C17: 1150 | D17: 1150 | E17: 1150 | F17: 1150 | G17: 1150 | H17: 1150 | I17: 1150 | J17: 2850 | L17: 2850 | N17: =SUM(B17:M17) -> 14900
A18: מתנות ומזכרות | N18: =SUM(B18:M18) -> 0
A19: קניית דירה/ שכירות | N19: =SUM(B19:M19) -> 0
A20: רכב ותחבורה | N20: =SUM(B20:M20) -> 0
A21: שונות | N21: =SUM(B21:M21) -> 0
A22: שירותי בנקאות | N22: =SUM(B22:M22) -> 0
A23: תרבות ופנאי | N23: =SUM(B23:M23) -> 0
A24: השקעות (בנק) | C24: 22000 | F24: 40000 | G24: 15000 | H24: 23000 | N24: =SUM(B24:M24) -> 100000
A25: חיסכון (בנק) | N25: 0
A26: חיסכון (מיטב) | G26: 5000 | N26: =SUM(B26:M26) -> 5000
A27: סה"כ הוצאות ידני | B27: =SUM(B2:B26) -> 3000.85 | C27: =SUM(C2:C26) -> 26929.15 | D27: =SUM(D2:D26) -> 3590.11 | E27: =SUM(E2:E26) -> 4870.04 | F27: =SUM(F2:F26) -> 43006.43 | G27: =SUM(G2:G26) -> 24763.43 | H27: =SUM(H2:H26) -> 26049.04 | I27: =SUM(I2:I26) -> 4743.52 | ... M27: =SUM(M2:M26) -> 3812.73 | N27: =SUM(B27:M27) -> 153964.06

Sheet 1
A1: כרטיס | B1: בית עסק | C1: תאריך עסקה | D1: סכום העסקה | E1: מנפיק | F1: סוג העסקה | G1: פירוט | H1: תאריך החיוב | I1: סכום לחיוב | J1: פירוט נוסף | K1: סוג כרטיס | L1: סוג הוצאה | M1: סכום הוצאה | N1: הערות פנימיות
A2: ויזה 7520 | B2: בריין בינה בעמ | C2: 31/12/2025 | D2: 37 | E2: כאל | F2: ישראל | H2: 02/01/2026 | I2: 37 | K2: =IF(A2>0,VLOOKUP(A2,טבלאות!$J:$K,2,0),"") -> אשראי מיכה | L2: =IF(ISERROR(VLOOKUP(B2,טבלאות!$G:$H,2,0)),"",VLOOKUP(B2,טבלאות!$G:$H,2,0)) -> מוצרי חשמל ותקשורת | M2: =IF(OR(L2="",L2="?"),"",IF(L2>0,I2,"")) -> 37
A3: ויזה 7520 | B3: PAYPAL *NETFLIX COM | C3: 30/12/2025 | D3: 69.9 | E3: כאל | F3: חו"ל | G3: הוראת קבע הולנד . מזהה כרטיס אינטרנט 4470 | H3: 02/01/2026 | I3: 69.9 | K3: =IF(A3>0,VLOOKUP(A3,טבלאות!$J:$K,2,0),"") -> אשראי מיכה | L3: =IF(ISERROR(VLOOKUP(B3,טבלאות!$G:$H,2,0)),"",VLOOKUP(B3,טבלאות!$G:$H,2,0)) -> מוצרי חשמל ותקשורת | M3: =IF(OR(L3="",L3="?"),"",IF(L3>0,I3,"")) -> 69.9
A4: ויזה 7520 | B4: גליקסמן שיווק ביצים | C4: 30/12/2025 | D4: 72 | E4: כאל | F4: ישראל | H4: 02/01/2026 | I4: 72 | K4: =IF(A4>0,VLOOKUP(A4,טבלאות!$J:$K,2,0),"") -> אשראי מיכה | L4: =IF(ISERROR(VLOOKUP(B4,טבלאות!$G:$H,2,0)),"",VLOOKUP(B4,טבלאות!$G:$H,2,0)) -> מזון ומשקאות | M4: =IF(OR(L4="",L4="?"),"",IF(L4>0,I4,"")) -> 72
A5: ויזה 7520 | B5: מ. יוחננוף ובניו- רחובות | C5: 30/12/2025 | D5: 1050.03 | E5: כאל | F5: ישראל | H5: 02/01/2026 | I5: 1050.03 | K5: =IF(A5>0,VLOOKUP(A5,טבלאות!$J:$K,2,0),"") -> אשראי מיכה | L5: =IF(ISERROR(VLOOKUP(B5,טבלאות!$G:$H,2,0)),"",VLOOKUP(B5,טבלאות!$G:$H,2,0)) -> מזון ומשקאות | M5: =IF(OR(L5="",L5="?"),"",IF(L5>0,I5,"")) -> 1050.03
A6: ויזה 3669 | B6: דלק מנטה קמעונאות דרכים ב | C6: 30/12/2025 | D6: 233.28 | E6: כאל | F6: ישראל | H6: 02/01/2026 | I6: 233.28 | K6: =IF(A6>0,VLOOKUP(A6,טבלאות!$J:$K,2,0),"") -> אשראי אורנה | L6: =IF(ISERROR(VLOOKUP(B6,טבלאות!$G:$H,2,0)),"",VLOOKUP(B6,טבלאות!$G:$H,2,0)) -> רכב ותחבורה | M6: =IF(OR(L6="",L6="?"),"",IF(L6>0,I6,"")) -> 233.28
A7: ויזה 7520 | B7: גולן טלקום | C7: 29/12/2025 | D7: 310.82 | E7: כאל | F7: ישראל | G7: הוראת קבע | H7: 02/01/2026 | I7: 310.82 | K7: =IF(A7>0,VLOOKUP(A7,טבלאות!$J:$K,2,0),"") -> אשראי מיכה | L7: =IF(ISERROR(VLOOKUP(B7,טבלאות!$G:$H,2,0)),"",VLOOKUP(B7,טבלאות!$G:$H,2,0)) -> מוצרי חשמל ותקשורת | M7: =IF(OR(L7="",L7="?"),"",IF(L7>0,I7,"")) -> 310.82
A8: ויזה 7520 | B8: דוכן הפרדסן מקס איט ניכיו | C8: 29/12/2025 | D8: 48.66 | E8: כאל | F8: ישראל | H8: 02/01/2026 | I8: 48.66 | K8: =IF(A8>0,VLOOKUP(A8,טבלאות!$J:$K,2,0),"") -> אשראי מיכה | L8: =IF(ISERROR(VLOOKUP(B8,טבלאות!$G:$H,2,0)),"",VLOOKUP(B8,טבלאות!$G:$H,2,0)) -> מזון ומשקאות | M8: =IF(OR(L8="",L8="?"),"",IF(L8>0,I8,"")) -> 48.66
A9: ויזה 7520 | B9: נאייקס ישראל חניונים | C9: 28/12/2025 | D9: 35 | E9: כאל | F9: ישראל | H9: 02/01/2026 | I9: 35 | K9: =IF(A9>0,VLOOKUP(A9,טבלאות!$J:$K,2,0),"") -> אשראי מיכה | L9: =IF(ISERROR(VLOOKUP(B9,טבלאות!$G:$H,2,0)),"",VLOOKUP(B9,טבלאות!$G:$H,2,0)) -> רכב ותחבורה | M9: =IF(OR(L9="",L9="?"),"",IF(L9>0,I9,"")) -> 35
A10: ויזה 3669 | B10: ביטוח ישיר ביטוח רכב | C10: 28/12/2025 | D10: 43 | E10: כאל | F10: ישראל | G10: הוראת קבע חדשה בכרטיס | H10: 02/01/2026 | I10: 43 | K10: =IF(A10>0,VLOOKUP(A10,טבלאות!$J:$K,2,0),"") -> אשראי אורנה | L10: =IF(ISERROR(VLOOKUP(B10,טבלאות!$G:$H,2,0)),"",VLOOKUP(B10,טבלאות!$G:$H,2,0)) -> רכב ותחבורה | M10: =IF(OR(L10="",L10="?"),"",IF(L10>0,I10,"")) -> 43
A11: ויזה 7520 | B11: טיב טעם רשתות רחובות | C11: 27/12/2025 | D11: 129.8 | E11: כאל | F11: ישראל | H11: 02/01/2026 | I11: 129.8 | K11: =IF(A11>0,VLOOKUP(A11,טבלאות!$J:$K,2,0),"") -> אשראי מיכה | L11: =IF(ISERROR(VLOOKUP(B11,טבלאות!$G:$H,2,0)),"",VLOOKUP(B11,טבלאות!$G:$H,2,0)) -> מזון ומשקאות | M11: =IF(OR(L11="",L11="?"),"",IF(L11>0,I11,"")) -> 129.8
A12: ויזה 7520 | B12: קואופ רחובות | C12: 26/12/2025 | D12: 114.16 | E12: כאל | F12: ישראל | H12: 02/01/2026 | I12: 114.16 | K12: =IF(A12>0,VLOOKUP(A12,טבלאות!$J:$K,2,0),"") -> אשראי מיכה | L12: =IF(ISERROR(VLOOKUP(B12,טבלאות!$G:$H,2,0)),"",VLOOKUP(B12,טבלאות!$G:$H,2,0)) -> מזון ומשקאות | M12: =IF(OR(L12="",L12="?"),"",IF(L12>0,I12,"")) -> 114.16
A13: ויזה 7520 | B13: קואופ רחובות | C13: 26/12/2025 | D13: 96.32 | E13: כאל | F13: ישראל | H13: 02/01/2026 | I13: 96.32 | K13: =IF(A13>0,VLOOKUP(A13,טבלאות!$J:$K,2,0),"") -> אשראי מיכה | L13: =IF(ISERROR(VLOOKUP(B13,טבלאות!$G:$H,2,0)),"",VLOOKUP(B13,טבלאות!$G:$H,2,0)) -> מזון ומשקאות | M13: =IF(OR(L13="",L13="?"),"",IF(L13>0,I13,"")) -> 96.32
A14: ויזה 7520 | B14: CELLO | C14: 26/12/2025 | D14: 52.28 | E14: כאל | F14: ישראל | G14: הוראת קבע | H14: 02/01/2026 | I14: 52.28 | K14: =IF(A14>0,VLOOKUP(A14,טבלאות!$J:$K,2,0),"") -> אשראי מיכה | L14: =IF(ISERROR(VLOOKUP(B14,טבלאות!$G:$H,2,0)),"",VLOOKUP(B14,טבלאות!$G:$H,2,0)) -> רכב ותחבורה | M14: =IF(OR(L14="",L14="?"),"",IF(L14>0,I14,"")) -> 52.28
A15: ויזה 3669 | B15: העברה ב BIT בנה"פ | C15: 26/12/2025 | D15: 60 | E15: כאל | F15: ישראל | G15: העברה למאיה שליטו | H15: 02/01/2026 | I15: 60 | K15: =IF(A15>0,VLOOKUP(A15,טבלאות!$J:$K,2,0),"") -> אשראי אורנה | L15: =IF(ISERROR(VLOOKUP(B15,טבלאות!$G:$H,2,0)),"",VLOOKUP(B15,טבלאות!$G:$H,2,0)) -> חוגים | M15: =IF(OR(L15="",L15="?"),"",IF(L15>0,I15,"")) -> 60
A16: ויזה 3669 | B16: אורט רב מוטב | C16: 25/12/2025 | D16: 8956 | E16: כאל | F16: תשלום-ישראל | G16: 1 מ - 12 | H16: 02/01/2026 | I16: 750 | K16: =IF(A16>0,VLOOKUP(A16,טבלאות!$J:$K,2,0),"") -> אשראי אורנה | L16: =IF(ISERROR(VLOOKUP(B16,טבלאות!$G:$H,2,0)),"",VLOOKUP(B16,טבלאות!$G:$H,2,0)) -> בית ספר | M16: =IF(OR(L16="",L16="?"),"",IF(L16>0,I16,"")) -> 750
A17: ויזה 3669 | B17: הראל ביטוח חיים | C17: 25/12/2025 | D17: 56.93 | E17: כאל | F17: ישראל | G17: הוראת קבע | H17: 02/01/2026 | I17: 56.93 | K17: =IF(A17>0,VLOOKUP(A17,טבלאות!$J:$K,2,0),"") -> אשראי אורנה | L17: =IF(ISERROR(VLOOKUP(B17,טבלאות!$G:$H,2,0)),"",VLOOKUP(B17,טבלאות!$G:$H,2,0)) -> ביטוח | M17: =IF(OR(L17="",L17="?"),"",IF(L17>0,I17,"")) -> 56.93
A18: ויזה 3669 | B18: PAYBOX | C18: 24/12/2025 | D18: 260 | E18: כאל | F18: ישראל | G18: העברה לשרית קרת עבור שיעורים אמיר והילה | H18: 02/01/2026 | I18: 260 | K18: =IF(A18>0,VLOOKUP(A18,טבלאות!$J:$K,2,0),"") -> אשראי אורנה | L18: =IF(ISERROR(VLOOKUP(B18,טבלאות!$G:$H,2,0)),"",VLOOKUP(B18,טבלאות!$G:$H,2,0)) -> חוגים | M18: =IF(OR(L18="",L18="?"),"",IF(L18>0,I18,"")) -> 260
A19: ויזה 7520 | B19: שרותי בריאות כללית הו"ק | C19: 23/12/2025 | D19: 62.81 | E19: כאל | F19: ישראל | G19: הוראת קבע | H19: 02/01/2026 | I19: 62.81 | K19: =IF(A19>0,VLOOKUP(A19,טבלאות!$J:$K,2,0),"") -> אשראי מיכה | L19: =IF(ISERROR(VLOOKUP(B19,טבלאות!$G:$H,2,0)),"",VLOOKUP(B19,טבלאות!$G:$H,2,0)) -> בריאות | M19: =IF(OR(L19="",L19="?"),"",IF(L19>0,I19,"")) -> 62.81
A20: ויזה 7520 | B20: זול סטוק יפו | C20: 23/12/2025 | D20: 43.5 | E20: כאל | F20: ישראל | H20: 02/01/2026 | I20: 43.5 | K20: =IF(A20>0,VLOOKUP(A20,טבלאות!$J:$K,2,0),"") -> אשראי מיכה | L20: =IF(ISERROR(VLOOKUP(B20,טבלאות!$G:$H,2,0)),"",VLOOKUP(B20,טבלאות!$G:$H,2,0)) -> בית וגן | M20: =IF(OR(L20="",L20="?"),"",IF(L20>0,I20,"")) -> 43.5
A21: ויזה 7520 | B21: סעוד הראל -כללית | C21: 23/12/2025 | D21: 128.23 | E21: כאל | F21: ישראל | G21: הוראת קבע | H21: 02/01/2026 | I21: 128.23 | K21: =IF(A21>0,VLOOKUP(A21,טבלאות!$J:$K,2,0),"") -> אשראי מיכה | L21: =IF(ISERROR(VLOOKUP(B21,טבלאות!$G:$H,2,0)),"",VLOOKUP(B21,טבלאות!$G:$H,2,0)) -> בריאות | M21: =IF(OR(L21="",L21="?"),"",IF(L21>0,I21,"")) -> 128.23
A22: ויזה 7520 | B22: גליקסמן שיווק ביצים | C22: 23/12/2025 | D22: 72 | E22: כאל | F22: ישראל | H22: 02/01/2026 | I22: 72 | K22: =IF(A22>0,VLOOKUP(A22,טבלאות!$J:$K,2,0),"") -> אשראי מיכה | L22: =IF(ISERROR(VLOOKUP(B22,טבלאות!$G:$H,2,0)),"",VLOOKUP(B22,טבלאות!$G:$H,2,0)) -> מזון ומשקאות | M22: =IF(OR(L22="",L22="?"),"",IF(L22>0,I22,"")) -> 72
A23: ויזה 7520 | B23: מ. יוחננוף ובניו- רחובות | C23: 23/12/2025 | D23: 544.19 | E23: כאל | F23: ישראל | H23: 02/01/2026 | I23: 544.19 | K23: =IF(A23>0,VLOOKUP(A23,טבלאות!$J:$K,2,0),"") -> אשראי מיכה | L23: =IF(ISERROR(VLOOKUP(B23,טבלאות!$G:$H,2,0)),"",VLOOKUP(B23,טבלאות!$G:$H,2,0)) -> מזון ומשקאות | M23: =IF(OR(L23="",L23="?"),"",IF(L23>0,I23,"")) -> 544.19
A24: ויזה 7520 | B24: סופר-פארם מרכז הנשיא רחוב | C24: 22/12/2025 | D24: 19.8 | E24: כאל | F24: ישראל | H24: 02/01/2026 | I24: 19.8 | K24: =IF(A24>0,VLOOKUP(A24,טבלאות!$J:$K,2,0),"") -> אשראי מיכה | L24: =IF(ISERROR(VLOOKUP(B24,טבלאות!$G:$H,2,0)),"",VLOOKUP(B24,טבלאות!$G:$H,2,0)) -> בריאות | M24: =IF(OR(L24="",L24="?"),"",IF(L24>0,I24,"")) -> 19.8
A25: ויזה 7520 | B25: BIT | C25: 21/12/2025 | D25: 150 | E25: כאל | F25: חו"ל | G25: ישראל . העברה לאסתי אילוז | H25: 02/01/2026 | I25: 150 | K25: =IF(A25>0,VLOOKUP(A25,טבלאות!$J:$K,2,0),"") -> אשראי מיכה | L25: =IF(ISERROR(VLOOKUP(B25,טבלאות!$G:$H,2,0)),"",VLOOKUP(B25,טבלאות!$G:$H,2,0)) -> מתנות ומזכרות | M25: =IF(OR(L25="",L25="?"),"",IF(L25>0,I25,"")) -> 150
A26: ויזה 7520 | B26: סופר-פארם מרכז הנשיא רחוב | C26: 21/12/2025 | D26: 61.7 | E26: כאל | F26: ישראל | H26: 02/01/2026 | I26: 61.7 | K26: =IF(A26>0,VLOOKUP(A26,טבלאות!$J:$K,2,0),"") -> אשראי מיכה | L26: =IF(ISERROR(VLOOKUP(B26,טבלאות!$G:$H,2,0)),"",VLOOKUP(B26,טבלאות!$G:$H,2,0)) -> בריאות | M26: =IF(OR(L26="",L26="?"),"",IF(L26>0,I26,"")) -> 61.7
A27: ויזה 3669 | B27: בזק הוראות קבע | C27: 21/12/2025 | D27: 163.57 | E27: כאל | F27: ישראל | G27: הוראת קבע | H27: 02/01/2026 | I27: 163.57 | K27: =IF(A27>0,VLOOKUP(A27,טבלאות!$J:$K,2,0),"") -> אשראי אורנה | L27: =IF(ISERROR(VLOOKUP(B27,טבלאות!$G:$H,2,0)),"",VLOOKUP(B27,טבלאות!$G:$H,2,0)) -> מוצרי חשמל ותקשורת | M27: =IF(OR(L27="",L27="?"),"",IF(L27>0,I27,"")) -> 163.57
A28: ויזה 7520 | B28: דוכן הפרדסן מקס איט ניכיו | C28: 20/12/2025 | D28: 42.77 | E28: כאל | F28: ישראל | H28: 02/01/2026 | I28: 42.77 | K28: =IF(A28>0,VLOOKUP(A28,טבלאות!$J:$K,2,0),"") -> אשראי מיכה | L28: =IF(ISERROR(VLOOKUP(B28,טבלאות!$G:$H,2,0)),"",VLOOKUP(B28,טבלאות!$G:$H,2,0)) -> מזון ומשקאות | M28: =IF(OR(L28="",L28="?"),"",IF(L28>0,I28,"")) -> 42.77
A29: ויזה 7520 | B29: BIT | C29: 19/12/2025 | D29: 120 | E29: כאל | F29: חו"ל | G29: ישראל . העברה לטליה סלמון | H29: 02/01/2026 | I29: 120 | K29: =IF(A29>0,VLOOKUP(A29,טבלאות!$J:$K,2,0),"") -> אשראי מיכה | L29: =IF(ISERROR(VLOOKUP(B29,טבלאות!$G:$H,2,0)),"",VLOOKUP(B29,טבלאות!$G:$H,2,0)) -> מתנות ומזכרות | M29: =IF(OR(L29="",L29="?"),"",IF(L29>0,I29,"")) -> 120
A30: ויזה 3669 | B30: PAYBOX | C30: 19/12/2025 | D30: 130 | E30: כאל | F30: ישראל | G30: העברה לשרית קרת עבור שיעור לירון | H30: 02/01/2026 | I30: 130 | K30: =IF(A30>0,VLOOKUP(A30,טבלאות!$J:$K,2,0),"") -> אשראי אורנה | L30: =IF(ISERROR(VLOOKUP(B30,טבלאות!$G:$H,2,0)),"",VLOOKUP(B30,טבלאות!$G:$H,2,0)) -> חוגים | M30: =IF(OR(L30="",L30="?"),"",IF(L30>0,I30,"")) -> 130
A31: ויזה 7520 | B31: PAYPAL *ZWIFT | C31: 18/12/2025 | D31: 66.52 | E31: כאל | F31: חו"ל | G31: הוראת קבע ארצות הברית . מזהה כרטיס אינטרנט 4470 | H31: 02/01/2026 | I31: 66.52 | K31: =IF(A31>0,VLOOKUP(A31,טבלאות!$J:$K,2,0),"") -> אשראי מיכה | L31: =IF(ISERROR(VLOOKUP(B31,טבלאות!$G:$H,2,0)),"",VLOOKUP(B31,טבלאות!$G:$H,2,0)) -> בית וגן | M31: =IF(OR(L31="",L31="?"),"",IF(L31>0,I31,"")) -> 66.52
A32: ויזה 7520 | B32: גליקסמן שיווק ביצים | C32: 17/12/2025 | D32: 36 | E32: כאל | F32: ישראל | H32: 02/01/2026 | I32: 36 | K32: =IF(A32>0,VLOOKUP(A32,טבלאות!$J:$K,2,0),"") -> אשראי מיכה | L32: =IF(ISERROR(VLOOKUP(B32,טבלאות!$G:$H,2,0)),"",VLOOKUP(B32,טבלאות!$G:$H,2,0)) -> מזון ומשקאות | M32: =IF(OR(L32="",L32="?"),"",IF(L32>0,I32,"")) -> 36
A33: ויזה 7520 | B33: מ. יוחננוף ובניו- רחובות | C33: 17/12/2025 | D33: 998.86 | E33: כאל | F33: ישראל | H33: 02/01/2026 | I33: 998.86 | K33: =IF(A33>0,VLOOKUP(A33,טבלאות!$J:$K,2,0),"") -> אשראי מיכה | L33: =IF(ISERROR(VLOOKUP(B33,טבלאות!$G:$H,2,0)),"",VLOOKUP(B33,טבלאות!$G:$H,2,0)) -> מזון ומשקאות | M33: =IF(OR(L33="",L33="?"),"",IF(L33>0,I33,"")) -> 998.86
A34: ויזה 3669 | B34: PAYBOX | C34: 17/12/2025 | D34: 260 | E34: כאל | F34: ישראל | G34: העברה לשרית קרת עבור שיעורים אמיר והילה | H34: 02/01/2026 | I34: 260 | K34: =IF(A34>0,VLOOKUP(A34,טבלאות!$J:$K,2,0),"") -> אשראי אורנה | L34: =IF(ISERROR(VLOOKUP(B34,טבלאות!$G:$H,2,0)),"",VLOOKUP(B34,טבלאות!$G:$H,2,0)) -> חוגים | M34: =IF(OR(L34="",L34="?"),"",IF(L34>0,I34,"")) -> 260
A35: ויזה 3669 | B35: חברת החשמל לישראל בע"מ | C35: 17/12/2025 | D35: 970.87 | E35: כאל | F35: ישראל | G35: הוראת קבע | H35: 02/01/2026 | I35: 970.87 | K35: =IF(A35>0,VLOOKUP(A35,טבלאות!$J:$K,2,0),"") -> אשראי אורנה | L35: =IF(ISERROR(VLOOKUP(B35,טבלאות!$G:$H,2,0)),"",VLOOKUP(B35,טבלאות!$G:$H,2,0)) -> מוצרי חשמל ותקשורת | M35: =IF(OR(L35="",L35="?"),"",IF(L35>0,I35,"")) -> 970.87
A36: ויזה 7520 | B36: מ. יוחננוף ובניו- רחובות | C36: 16/12/2025 | D36: 65.39 | E36: כאל | F36: ישראל | H36: 02/01/2026 | I36: 65.39 | K36: =IF(A36>0,VLOOKUP(A36,טבלאות!$J:$K,2,0),"") -> אשראי מיכה | L36: =IF(ISERROR(VLOOKUP(B36,טבלאות!$G:$H,2,0)),"",VLOOKUP(B36,טבלאות!$G:$H,2,0)) -> מזון ומשקאות | M36: =IF(OR(L36="",L36="?"),"",IF(L36>0,I36,"")) -> 65.39
A37: ויזה 3669 | B37: דלק מנטה קמעונאות דרכים ב | C37: 16/12/2025 | D37: 214.84 | E37: כאל | F37: ישראל | H37: 02/01/2026 | I37: 214.84 | K37: =IF(A37>0,VLOOKUP(A37,טבלאות!$J:$K,2,0),"") -> אשראי אורנה | L37: =IF(ISERROR(VLOOKUP(B37,טבלאות!$G:$H,2,0)),"",VLOOKUP(B37,טבלאות!$G:$H,2,0)) -> רכב ותחבורה | M37: =IF(OR(L37="",L37="?"),"",IF(L37>0,I37,"")) -> 214.84
A38: ויזה 7520 | B38: מחסני השוק רחובות הנשיא | C38: 15/12/2025 | D38: 42.08 | E38: כאל | F38: ישראל | H38: 02/01/2026 | I38: 42.08 | K38: =IF(A38>0,VLOOKUP(A38,טבלאות!$J:$K,2,0),"") -> אשראי מיכה | L38: =IF(ISERROR(VLOOKUP(B38,טבלאות!$G:$H,2,0)),"",VLOOKUP(B38,טבלאות!$G:$H,2,0)) -> מזון ומשקאות | M38: =IF(OR(L38="",L38="?"),"",IF(L38>0,I38,"")) -> 42.08
A39: ויזה 3669 | B39: תשלום ועד בית | C39: 15/12/2025 | D39: 350 | E39: כאל | F39: ישראל | H39: 02/01/2026 | I39: 350 | K39: =IF(A39>0,VLOOKUP(A39,טבלאות!$J:$K,2,0),"") -> אשראי אורנה | L39: =IF(ISERROR(VLOOKUP(B39,טבלאות!$G:$H,2,0)),"",VLOOKUP(B39,טבלאות!$G:$H,2,0)) -> בית וגן | M39: =IF(OR(L39="",L39="?"),"",IF(L39>0,I39,"")) -> 350
A40: ויזה 7520 | B40: טיב טעם רשתות רחובות | C40: 13/12/2025 | D40: 58.8 | E40: כאל | F40: ישראל | H40: 02/01/2026 | I40: 58.8 | K40: =IF(A40>0,VLOOKUP(A40,טבלאות!$J:$K,2,0),"") -> אשראי מיכה | L40: =IF(ISERROR(VLOOKUP(B40,טבלאות!$G:$H,2,0)),"",VLOOKUP(B40,טבלאות!$G:$H,2,0)) -> מזון ומשקאות | M40: =IF(OR(L40="",L40="?"),"",IF(L40>0,I40,"")) -> 58.8
...

Sheet 2
A1: כרטיס | B1: בית עסק | C1: תאריך עסקה | D1: סכום העסקה | E1: מנפיק | F1: סוג העסקה | G1: פירוט | H1: תאריך החיוב | I1: סכום לחיוב | J1: פירוט נוסף | K1: סוג כרטיס | L1: סוג הוצאה | M1: סכום הוצאה | N1: הערות פנימיות
A2: ויזה 7520 | B2: טיב טעם רשתות רחובות | C2: 31/01/2026 | D2: 130.4 | E2: כאל | F2: ישראל | H2: 02/02/2026 | I2: 130.4 | K2: =IF(A2>0,VLOOKUP(A2,טבלאות!$J:$K,2,0),"") -> אשראי מיכה | L2: =IF(ISERROR(VLOOKUP(B2,טבלאות!$G:$H,2,0)),"",VLOOKUP(B2,טבלאות!$G:$H,2,0)) -> מזון ומשקאות | M2: =IF(OR(L2="",L2="?"),"",IF(L2>0,I2,"")) -> 130.4
A3: ויזה 7520 | B3: דוכן הפרדסן מקס איט ניכיו | C3: 31/01/2026 | D3: 13.15 | E3: כאל | F3: ישראל | H3: 02/02/2026 | I3: 13.15 | K3: =IF(A3>0,VLOOKUP(A3,טבלאות!$J:$K,2,0),"") -> אשראי מיכה | L3: =IF(ISERROR(VLOOKUP(B3,טבלאות!$G:$H,2,0)),"",VLOOKUP(B3,טבלאות!$G:$H,2,0)) -> מזון ומשקאות | M3: =IF(OR(L3="",L3="?"),"",IF(L3>0,I3,"")) -> 13.15
A4: ויזה 7520 | B4: בריין בינה בעמ | C4: 31/01/2026 | D4: 37 | E4: כאל | F4: ישראל | H4: 02/02/2026 | I4: 37 | K4: =IF(A4>0,VLOOKUP(A4,טבלאות!$J:$K,2,0),"") -> אשראי מיכה | L4: =IF(ISERROR(VLOOKUP(B4,טבלאות!$G:$H,2,0)),"",VLOOKUP(B4,טבלאות!$G:$H,2,0)) -> מוצרי חשמל ותקשורת | M4: =IF(OR(L4="",L4="?"),"",IF(L4>0,I4,"")) -> 37
A5: ויזה 7520 | B5: דור אלון פארק המדע | C5: 31/01/2026 | D5: 210.46 | E5: כאל | F5: ישראל | H5: 02/02/2026 | I5: 210.46 | K5: =IF(A5>0,VLOOKUP(A5,טבלאות!$J:$K,2,0),"") -> אשראי מיכה | L5: =IF(ISERROR(VLOOKUP(B5,טבלאות!$G:$H,2,0)),"",VLOOKUP(B5,טבלאות!$G:$H,2,0)) -> רכב ותחבורה | M5: =IF(OR(L5="",L5="?"),"",IF(L5>0,I5,"")) -> 210.46
A6: ויזה 7520 | B6: טיב טעם רשתות רחובות | C6: 31/01/2026 | D6: 29.4 | E6: כאל | F6: ישראל | H6: 02/02/2026 | I6: 29.4 | K6: =IF(A6>0,VLOOKUP(A6,טבלאות!$J:$K,2,0),"") -> אשראי מיכה | L6: =IF(ISERROR(VLOOKUP(B6,טבלאות!$G:$H,2,0)),"",VLOOKUP(B6,טבלאות!$G:$H,2,0)) -> מזון ומשקאות | M6: =IF(OR(L6="",L6="?"),"",IF(L6>0,I6,"")) -> 29.4
A7: ויזה 3669 | B7: העברה ב BIT בנה"פ | C7: 31/01/2026 | D7: 200 | E7: כאל | F7: ישראל | G7: העברה למרשה דוידוביץ | H7: 02/02/2026 | I7: 200 | K7: =IF(A7>0,VLOOKUP(A7,טבלאות!$J:$K,2,0),"") -> אשראי אורנה | L7: =IF(ISERROR(VLOOKUP(B7,טבלאות!$G:$H,2,0)),"",VLOOKUP(B7,טבלאות!$G:$H,2,0)) -> חוגים | M7: =IF(OR(L7="",L7="?"),"",IF(L7>0,I7,"")) -> 200
A8: ויזה 7520 | B8: PAYPAL *NETFLIX COM | C8: 30/01/2026 | D8: 69.9 | E8: כאל | F8: חו"ל | G8: הוראת קבע הולנד . מזהה כרטיס אינטרנט 4470 | H8: 02/02/2026 | I8: 69.9 | K8: =IF(A8>0,VLOOKUP(A8,טבלאות!$J:$K,2,0),"") -> אשראי מיכה | L8: =IF(ISERROR(VLOOKUP(B8,טבלאות!$G:$H,2,0)),"",VLOOKUP(B8,טבלאות!$G:$H,2,0)) -> מוצרי חשמל ותקשורת | M8: =IF(OR(L8="",L8="?"),"",IF(L8>0,I8,"")) -> 69.9
A9: ויזה 7520 | B9: קואופ רחובות | C9: 30/01/2026 | D9: 47.6 | E9: כאל | F9: ישראל | H9: 02/02/2026 | I9: 47.6 | K9: =IF(A9>0,VLOOKUP(A9,טבלאות!$J:$K,2,0),"") -> אשראי מיכה | L9: =IF(ISERROR(VLOOKUP(B9,טבלאות!$G:$H,2,0)),"",VLOOKUP(B9,טבלאות!$G:$H,2,0)) -> מזון ומשקאות | M9: =IF(OR(L9="",L9="?"),"",IF(L9>0,I9,"")) -> 47.6
A10: ויזה 7520 | B10: קואופ רחובות | C10: 29/01/2026 | D10: 5.9 | E10: כאל | F10: ישראל | H10: 02/02/2026 | I10: 5.9 | K10: =IF(A10>0,VLOOKUP(A10,טבלאות!$J:$K,2,0),"") -> אשראי מיכה | L10: =IF(ISERROR(VLOOKUP(B10,טבלאות!$G:$H,2,0)),"",VLOOKUP(B10,טבלאות!$G:$H,2,0)) -> מזון ומשקאות | M10: =IF(OR(L10="",L10="?"),"",IF(L10>0,I10,"")) -> 5.9
A11: ויזה 7520 | B11: מ. יוחננוף ובניו- רחובות | C11: 29/01/2026 | D11: 109.4 | E11: כאל | F11: ישראל | H11: 02/02/2026 | I11: 109.4 | K11: =IF(A11>0,VLOOKUP(A11,טבלאות!$J:$K,2,0),"") -> אשראי מיכה | L11: =IF(ISERROR(VLOOKUP(B11,טבלאות!$G:$H,2,0)),"",VLOOKUP(B11,טבלאות!$G:$H,2,0)) -> מזון ומשקאות | M11: =IF(OR(L11="",L11="?"),"",IF(L11>0,I11,"")) -> 109.4
A12: ויזה 7520 | B12: דוכן הפרדסן מקס איט ניכיו | C12: 29/01/2026 | D12: 65.92 | E12: כאל | F12: ישראל | H12: 02/02/2026 | I12: 65.92 | K12: =IF(A12>0,VLOOKUP(A12,טבלאות!$J:$K,2,0),"") -> אשראי מיכה | L12: =IF(ISERROR(VLOOKUP(B12,טבלאות!$G:$H,2,0)),"",VLOOKUP(B12,טבלאות!$G:$H,2,0)) -> מזון ומשקאות | M12: =IF(OR(L12="",L12="?"),"",IF(L12>0,I12,"")) -> 65.92
A13: ויזה 7520 | B13: גפניקה רחובות | C13: 29/01/2026 | D13: 74 | E13: כאל | F13: ישראל | H13: 02/02/2026 | I13: 74 | K13: =IF(A13>0,VLOOKUP(A13,טבלאות!$J:$K,2,0),"") -> אשראי מיכה | L13: =IF(ISERROR(VLOOKUP(B13,טבלאות!$G:$H,2,0)),"",VLOOKUP(B13,טבלאות!$G:$H,2,0)) -> בילוי ומסעדות | M13: =IF(OR(L13="",L13="?"),"",IF(L13>0,I13,"")) -> 74
A14: ויזה 7520 | B14: PAYPAL *ALIPAYSINGA | C14: 29/01/2026 | D14: -12.49 | E14: כאל | F14: זיכוי-חו"ל | G14: סינגפור בגין עסקה שבוצעה במזהה כרטיס אינטרנט 4470 | H14: 02/02/2026 | I14: -12.49 | K14: =IF(A14>0,VLOOKUP(A14,טבלאות!$J:$K,2,0),"") -> אשראי מיכה | L14: =IF(ISERROR(VLOOKUP(B14,טבלאות!$G:$H,2,0)),"",VLOOKUP(B14,טבלאות!$G:$H,2,0)) -> מוצרי חשמל ותקשורת | M14: =IF(OR(L14="",L14="?"),"",IF(L14>0,I14,"")) -> -12.49
A15: ויזה 7520 | B15: כלל ביטוח חיים הו"ק | C15: 28/01/2026 | D15: 80 | E15: כאל | F15: ישראל | G15: הוראת קבע | H15: 02/02/2026 | I15: 80 | K15: =IF(A15>0,VLOOKUP(A15,טבלאות!$J:$K,2,0),"") -> אשראי מיכה | L15: =IF(ISERROR(VLOOKUP(B15,טבלאות!$G:$H,2,0)),"",VLOOKUP(B15,טבלאות!$G:$H,2,0)) -> ביטוח | M15: =IF(OR(L15="",L15="?"),"",IF(L15>0,I15,"")) -> 80
A16: ויזה 7520 | B16: גולן טלקום | C16: 28/01/2026 | D16: 134.24 | E16: כאל | F16: ישראל | G16: הוראת קבע | H16: 02/02/2026 | I16: 134.24 | K16: =IF(A16>0,VLOOKUP(A16,טבלאות!$J:$K,2,0),"") -> אשראי מיכה | L16: =IF(ISERROR(VLOOKUP(B16,טבלאות!$G:$H,2,0)),"",VLOOKUP(B16,טבלאות!$G:$H,2,0)) -> מוצרי חשמל ותקשורת | M16: =IF(OR(L16="",L16="?"),"",IF(L16>0,I16,"")) -> 134.24
A17: ויזה 3669 | B17: PAYBOX | C17: 28/01/2026 | D17: 260 | E17: כאל | F17: ישראל | G17: העברה לשרית קרת עבור שיעורים אמיר והילה | H17: 02/02/2026 | I17: 260 | K17: =IF(A17>0,VLOOKUP(A17,טבלאות!$J:$K,2,0),"") -> אשראי אורנה | L17: =IF(ISERROR(VLOOKUP(B17,טבלאות!$G:$H,2,0)),"",VLOOKUP(B17,טבלאות!$G:$H,2,0)) -> חוגים | M17: =IF(OR(L17="",L17="?"),"",IF(L17>0,I17,"")) -> 260
A18: ויזה 7520 | B18: CELLO | C18: 27/01/2026 | D18: 243.74 | E18: כאל | F18: ישראל | G18: הוראת קבע | H18: 02/02/2026 | I18: 243.74 | K18: =IF(A18>0,VLOOKUP(A18,טבלאות!$J:$K,2,0),"") -> אשראי מיכה | L18: =IF(ISERROR(VLOOKUP(B18,טבלאות!$G:$H,2,0)),"",VLOOKUP(B18,טבלאות!$G:$H,2,0)) -> רכב ותחבורה | M18: =IF(OR(L18="",L18="?"),"",IF(L18>0,I18,"")) -> 243.74
A19: ויזה 7520 | B19: גליקסמן שיווק ביצים | C19: 27/01/2026 | D19: 72 | E19: כאל | F19: ישראל | H19: 02/02/2026 | I19: 72 | K19: =IF(A19>0,VLOOKUP(A19,טבלאות!$J:$K,2,0),"") -> אשראי מיכה | L19: =IF(ISERROR(VLOOKUP(B19,טבלאות!$G:$H,2,0)),"",VLOOKUP(B19,טבלאות!$G:$H,2,0)) -> מזון ומשקאות | M19: =IF(OR(L19="",L19="?"),"",IF(L19>0,I19,"")) -> 72
A20: ויזה 7520 | B20: מ. יוחננוף ובניו- רחובות | C20: 27/01/2026 | D20: 799.82 | E20: כאל | F20: ישראל | H20: 02/02/2026 | I20: 799.82 | K20: =IF(A20>0,VLOOKUP(A20,טבלאות!$J:$K,2,0),"") -> אשראי מיכה | L20: =IF(ISERROR(VLOOKUP(B20,טבלאות!$G:$H,2,0)),"",VLOOKUP(B20,טבלאות!$G:$H,2,0)) -> מזון ומשקאות | M20: =IF(OR(L20="",L20="?"),"",IF(L20>0,I20,"")) -> 799.82
A21: ויזה 3669 | B21: העברה ב BIT בנה"פ | C21: 26/01/2026 | D21: 100 | E21: כאל | F21: ישראל | G21: העברה למרשה דוידוביץ | H21: 02/02/2026 | I21: 100 | K21: =IF(A21>0,VLOOKUP(A21,טבלאות!$J:$K,2,0),"") -> אשראי אורנה | L21: =IF(ISERROR(VLOOKUP(B21,טבלאות!$G:$H,2,0)),"",VLOOKUP(B21,טבלאות!$G:$H,2,0)) -> חוגים | M21: =IF(OR(L21="",L21="?"),"",IF(L21>0,I21,"")) -> 100
A22: ויזה 3669 | B22: חיוך נדיר | C22: 26/01/2026 | D22: 20 | E22: כאל | F22: ישראל | H22: 02/02/2026 | I22: 20 | K22: =IF(A22>0,VLOOKUP(A22,טבלאות!$J:$K,2,0),"") -> אשראי אורנה | L22: מזון ומשקאות | M22: =IF(OR(L22="",L22="?"),"",IF(L22>0,I22,"")) -> 20
A23: ויזה 3669 | B23: הראל ביטוח חיים | C23: 26/01/2026 | D23: 56.93 | E23: כאל | F23: ישראל | G23: הוראת קבע | H23: 02/02/2026 | I23: 56.93 | K23: =IF(A23>0,VLOOKUP(A23,טבלאות!$J:$K,2,0),"") -> אשראי אורנה | L23: =IF(ISERROR(VLOOKUP(B23,טבלאות!$G:$H,2,0)),"",VLOOKUP(B23,טבלאות!$G:$H,2,0)) -> ביטוח | M23: =IF(OR(L23="",L23="?"),"",IF(L23>0,I23,"")) -> 56.93
A24: ויזה 3669 | B24: מחסני השוק רחובות הנשיא | C24: 26/01/2026 | D24: 105.42 | E24: כאל | F24: ישראל | H24: 02/02/2026 | I24: 105.42 | K24: =IF(A24>0,VLOOKUP(A24,טבלאות!$J:$K,2,0),"") -> אשראי אורנה | L24: =IF(ISERROR(VLOOKUP(B24,טבלאות!$G:$H,2,0)),"",VLOOKUP(B24,טבלאות!$G:$H,2,0)) -> מזון ומשקאות | M24: =IF(OR(L24="",L24="?"),"",IF(L24>0,I24,"")) -> 105.42
A25: ויזה 7520 | B25: PAYPAL *AISGECOMMER | C25: 24/01/2026 | D25: 295.5 | E25: כאל | F25: חו"ל | G25: סינגפור . מזהה כרטיס אינטרנט 4470 | H25: 02/02/2026 | I25: 295.5 | K25: =IF(A25>0,VLOOKUP(A25,טבלאות!$J:$K,2,0),"") -> אשראי מיכה | L25: =IF(ISERROR(VLOOKUP(B25,טבלאות!$G:$H,2,0)),"",VLOOKUP(B25,טבלאות!$G:$H,2,0)) -> מתנות ומזכרות | M25: =IF(OR(L25="",L25="?"),"",IF(L25>0,I25,"")) -> 295.5
A26: ויזה 7520 | B26: BIT | C26: 23/01/2026 | D26: 42 | E26: כאל | F26: חו"ל | G26: ישראל . העברה למקסים חנדרוס | H26: 02/02/2026 | I26: 42 | K26: =IF(A26>0,VLOOKUP(A26,טבלאות!$J:$K,2,0),"") -> אשראי מיכה | L26: =IF(ISERROR(VLOOKUP(B26,טבלאות!$G:$H,2,0)),"",VLOOKUP(B26,טבלאות!$G:$H,2,0)) -> מתנות ומזכרות | M26: =IF(OR(L26="",L26="?"),"",IF(L26>0,I26,"")) -> 42
A27: ויזה 7520 | B27: קואופ רחובות | C27: 23/01/2026 | D27: 34.7 | E27: כאל | F27: ישראל | H27: 02/02/2026 | I27: 34.7 | K27: =IF(A27>0,VLOOKUP(A27,טבלאות!$J:$K,2,0),"") -> אשראי מיכה | L27: =IF(ISERROR(VLOOKUP(B27,טבלאות!$G:$H,2,0)),"",VLOOKUP(B27,טבלאות!$G:$H,2,0)) -> מזון ומשקאות | M27: =IF(OR(L27="",L27="?"),"",IF(L27>0,I27,"")) -> 34.7
A28: ויזה 7520 | B28: שרותי בריאות כללית הו"ק | C28: 22/01/2026 | D28: 68.39 | E28: כאל | F28: ישראל | G28: הוראת קבע | H28: 02/02/2026 | I28: 68.39 | K28: =IF(A28>0,VLOOKUP(A28,טבלאות!$J:$K,2,0),"") -> אשראי מיכה | L28: =IF(ISERROR(VLOOKUP(B28,טבלאות!$G:$H,2,0)),"",VLOOKUP(B28,טבלאות!$G:$H,2,0)) -> בריאות | M28: =IF(OR(L28="",L28="?"),"",IF(L28>0,I28,"")) -> 68.39
A29: ויזה 7520 | B29: סעוד הראל -כללית | C29: 22/01/2026 | D29: 128.24 | E29: כאל | F29: ישראל | G29: הוראת קבע | H29: 02/02/2026 | I29: 128.24 | K29: =IF(A29>0,VLOOKUP(A29,טבלאות!$J:$K,2,0),"") -> אשראי מיכה | L29: =IF(ISERROR(VLOOKUP(B29,טבלאות!$G:$H,2,0)),"",VLOOKUP(B29,טבלאות!$G:$H,2,0)) -> בריאות | M29: =IF(OR(L29="",L29="?"),"",IF(L29>0,I29,"")) -> 128.24
A30: ויזה 7520 | B30: מ. יוחננוף ובניו- רחובות | C30: 22/01/2026 | D30: 199.01 | E30: כאל | F30: ישראל | H30: 02/02/2026 | I30: 199.01 | K30: =IF(A30>0,VLOOKUP(A30,טבלאות!$J:$K,2,0),"") -> אשראי מיכה | L30: =IF(ISERROR(VLOOKUP(B30,טבלאות!$G:$H,2,0)),"",VLOOKUP(B30,טבלאות!$G:$H,2,0)) -> מזון ומשקאות | M30: =IF(OR(L30="",L30="?"),"",IF(L30>0,I30,"")) -> 199.01
A31: ויזה 7520 | B31: לחייל ולטייל-צמרת | C31: 22/01/2026 | D31: 19.9 | E31: כאל | F31: ישראל | H31: 02/02/2026 | I31: 19.9 | K31: =IF(A31>0,VLOOKUP(A31,טבלאות!$J:$K,2,0),"") -> אשראי מיכה | L31: =IF(ISERROR(VLOOKUP(B31,טבלאות!$G:$H,2,0)),"",VLOOKUP(B31,טבלאות!$G:$H,2,0)) -> נופש | M31: =IF(OR(L31="",L31="?"),"",IF(L31>0,I31,"")) -> 19.9
A32: ויזה 7520 | B32: דוכן הפרדסן מקס איט ניכיו | C32: 22/01/2026 | D32: 57.1 | E32: כאל | F32: ישראל | H32: 02/02/2026 | I32: 57.1 | K32: =IF(A32>0,VLOOKUP(A32,טבלאות!$J:$K,2,0),"") -> אשראי מיכה | L32: =IF(ISERROR(VLOOKUP(B32,טבלאות!$G:$H,2,0)),"",VLOOKUP(B32,טבלאות!$G:$H,2,0)) -> מזון ומשקאות | M32: =IF(OR(L32="",L32="?"),"",IF(L32>0,I32,"")) -> 57.1
A33: ויזה 3669 | B33: חיוך נדיר | C33: 22/01/2026 | D33: 20 | E33: כאל | F33: ישראל | H33: 02/02/2026 | I33: 20 | K33: =IF(A33>0,VLOOKUP(A33,טבלאות!$J:$K,2,0),"") -> אשראי אורנה | L33: מזון ומשקאות | M33: =IF(OR(L33="",L33="?"),"",IF(L33>0,I33,"")) -> 20
A34: ויזה 3669 | B34: חיוך נדיר | C34: 22/01/2026 | D34: 20 | E34: כאל | F34: ישראל | H34: 02/02/2026 | I34: 20 | K34: =IF(A34>0,VLOOKUP(A34,טבלאות!$J:$K,2,0),"") -> אשראי אורנה | L34: מזון ומשקאות | M34: =IF(OR(L34="",L34="?"),"",IF(L34>0,I34,"")) -> 20
A35: ויזה 7520 | B35: רשות האוכלוסין וההגירה ת | C35: 21/01/2026 | D35: 110 | E35: כאל | F35: ישראל | H35: 02/02/2026 | I35: 110 | K35: =IF(A35>0,VLOOKUP(A35,טבלאות!$J:$K,2,0),"") -> אשראי מיכה | L35: =IF(ISERROR(VLOOKUP(B35,טבלאות!$G:$H,2,0)),"",VLOOKUP(B35,טבלאות!$G:$H,2,0)) -> נופש | M35: =IF(OR(L35="",L35="?"),"",IF(L35>0,I35,"")) -> 110
A36: ויזה 7520 | B36: רשות האוכלוסין וההגירה ת | C36: 21/01/2026 | D36: 110 | E36: כאל | F36: ישראל | H36: 02/02/2026 | I36: 110 | K36: =IF(A36>0,VLOOKUP(A36,טבלאות!$J:$K,2,0),"") -> אשראי מיכה | L36: =IF(ISERROR(VLOOKUP(B36,טבלאות!$G:$H,2,0)),"",VLOOKUP(B36,טבלאות!$G:$H,2,0)) -> נופש | M36: =IF(OR(L36="",L36="?"),"",IF(L36>0,I36,"")) -> 110
A37: ויזה 7520 | B37: מ. יוחננוף ובניו- רחובות | C37: 21/01/2026 | D37: 104.64 | E37: כאל | F37: ישראל | H37: 02/02/2026 | I37: 104.64 | K37: =IF(A37>0,VLOOKUP(A37,טבלאות!$J:$K,2,0),"") -> אשראי מיכה | L37: =IF(ISERROR(VLOOKUP(B37,טבלאות!$G:$H,2,0)),"",VLOOKUP(B37,טבלאות!$G:$H,2,0)) -> מזון ומשקאות | M37: =IF(OR(L37="",L37="?"),"",IF(L37>0,I37,"")) -> 104.64
A38: ויזה 3669 | B38: PAYBOX | C38: 21/01/2026 | D38: 260 | E38: כאל | F38: ישראל | G38: העברה לשרית קרת עבור שיעורים אמיר והילה | H38: 02/02/2026 | I38: 260 | K38: =IF(A38>0,VLOOKUP(A38,טבלאות!$J:$K,2,0),"") -> אשראי אורנה | L38: =IF(ISERROR(VLOOKUP(B38,טבלאות!$G:$H,2,0)),"",VLOOKUP(B38,טבלאות!$G:$H,2,0)) -> חוגים | M38: =IF(OR(L38="",L38="?"),"",IF(L38>0,I38,"")) -> 260
A39: ויזה 7520 | B39: אופיס דיפו - נס ציונה | C39: 20/01/2026 | D39: 369.9 | E39: כאל | F39: ישראל | H39: 02/02/2026 | I39: 369.9 | K39: =IF(A39>0,VLOOKUP(A39,טבלאות!$J:$K,2,0),"") -> אשראי מיכה | L39: =IF(ISERROR(VLOOKUP(B39,טבלאות!$G:$H,2,0)),"",VLOOKUP(B39,טבלאות!$G:$H,2,0)) -> מתנות ומזכרות | M39: =IF(OR(L39="",L39="?"),"",IF(L39>0,I39,"")) -> 369.9
A40: ויזה 7520 | B40: גליקסמן שיווק ביצים | C40: 20/01/2026 | D40: 72 | E40: כאל | F40: ישראל | H40: 02/02/2026 | I40: 72 | K40: =IF(A40>0,VLOOKUP(A40,טבלאות!$J:$K,2,0),"") -> אשראי מיכה | L40: =IF(ISERROR(VLOOKUP(B40,טבלאות!$G:$H,2,0)),"",VLOOKUP(B40,טבלאות!$G:$H,2,0)) -> מזון ומשקאות | M40: =IF(OR(L40="",L40="?"),"",IF(L40>0,I40,"")) -> 72
...

Sheet 3
A1: כרטיס | B1: בית עסק | C1: תאריך עסקה | D1: סכום העסקה | E1: מנפיק | F1: סוג העסקה | G1: פירוט | H1: תאריך החיוב | I1: סכום לחיוב | J1: פירוט נוסף | K1: סוג כרטיס | L1: סוג הוצאה | M1: סכום הוצאה | N1: הערות פנימיות
A2: ויזה 7520 | B2: PAYPAL *NETFLIX COM | C2: 28/02/2026 | D2: 69.9 | E2: כאל | F2: חו"ל | G2: הוראת קבע הולנד . מזהה כרטיס אינטרנט 4470 | H2: 02/03/2026 | I2: 69.9 | K2: =IF(A2>0,VLOOKUP(A2,טבלאות!$J:$K,2,0),"") -> אשראי מיכה | L2: =IF(ISERROR(VLOOKUP(B2,טבלאות!$G:$H,2,0)),"",VLOOKUP(B2,טבלאות!$G:$H,2,0)) -> מוצרי חשמל ותקשורת | M2: =IF(OR(L2="",L2="?"),"",IF(L2>0,I2,"")) -> 69.9
A3: ויזה 7520 | B3: בריין בינה בעמ | C3: 28/02/2026 | D3: 37 | E3: כאל | F3: ישראל | H3: 02/03/2026 | I3: 37 | K3: =IF(A3>0,VLOOKUP(A3,טבלאות!$J:$K,2,0),"") -> אשראי מיכה | L3: =IF(ISERROR(VLOOKUP(B3,טבלאות!$G:$H,2,0)),"",VLOOKUP(B3,טבלאות!$G:$H,2,0)) -> מוצרי חשמל ותקשורת | M3: =IF(OR(L3="",L3="?"),"",IF(L3>0,I3,"")) -> 37
A4: ויזה 7520 | B4: קואופ רחובות | C4: 27/02/2026 | D4: 104.78 | E4: כאל | F4: ישראל | H4: 02/03/2026 | I4: 104.78 | K4: =IF(A4>0,VLOOKUP(A4,טבלאות!$J:$K,2,0),"") -> אשראי מיכה | L4: =IF(ISERROR(VLOOKUP(B4,טבלאות!$G:$H,2,0)),"",VLOOKUP(B4,טבלאות!$G:$H,2,0)) -> מזון ומשקאות | M4: =IF(OR(L4="",L4="?"),"",IF(L4>0,I4,"")) -> 104.78
A5: ויזה 7520 | B5: רונבי | C5: 27/02/2026 | D5: 119 | E5: כאל | F5: ישראל | H5: 02/03/2026 | I5: 119 | K5: =IF(A5>0,VLOOKUP(A5,טבלאות!$J:$K,2,0),"") -> אשראי מיכה | L5: =IF(ISERROR(VLOOKUP(B5,טבלאות!$G:$H,2,0)),"",VLOOKUP(B5,טבלאות!$G:$H,2,0)) -> בית וגן | M5: =IF(OR(L5="",L5="?"),"",IF(L5>0,I5,"")) -> 119
A6: ויזה 7520 | B6: יוחננוף - אחד העם | C6: 27/02/2026 | D6: 108.7 | E6: כאל | F6: ישראל | H6: 02/03/2026 | I6: 108.7 | K6: =IF(A6>0,VLOOKUP(A6,טבלאות!$J:$K,2,0),"") -> אשראי מיכה | L6: =IF(ISERROR(VLOOKUP(B6,טבלאות!$G:$H,2,0)),"",VLOOKUP(B6,טבלאות!$G:$H,2,0)) -> מזון ומשקאות | M6: =IF(OR(L6="",L6="?"),"",IF(L6>0,I6,"")) -> 108.7
A7: ויזה 7520 | B7: תמונות וחיוכים | C7: 27/02/2026 | D7: 529 | E7: כאל | F7: ישראל | H7: 02/03/2026 | I7: 529 | K7: =IF(A7>0,VLOOKUP(A7,טבלאות!$J:$K,2,0),"") -> אשראי מיכה | L7: =IF(ISERROR(VLOOKUP(B7,טבלאות!$G:$H,2,0)),"",VLOOKUP(B7,טבלאות!$G:$H,2,0)) -> מתנות ומזכרות | M7: =IF(OR(L7="",L7="?"),"",IF(L7>0,I7,"")) -> 529
A8: ויזה 7520 | B8: סופר-פארם מרכז הנשיא רחוב | C8: 27/02/2026 | D8: 37.3 | E8: כאל | F8: ישראל | H8: 02/03/2026 | I8: 37.3 | K8: =IF(A8>0,VLOOKUP(A8,טבלאות!$J:$K,2,0),"") -> אשראי מיכה | L8: =IF(ISERROR(VLOOKUP(B8,טבלאות!$G:$H,2,0)),"",VLOOKUP(B8,טבלאות!$G:$H,2,0)) -> בריאות | M8: =IF(OR(L8="",L8="?"),"",IF(L8>0,I8,"")) -> 37.3
A9: ויזה 7520 | B9: CELLO | C9: 26/02/2026 | D9: 145.52 | E9: כאל | F9: ישראל | G9: הוראת קבע | H9: 02/03/2026 | I9: 145.52 | K9: =IF(A9>0,VLOOKUP(A9,טבלאות!$J:$K,2,0),"") -> אשראי מיכה | L9: =IF(ISERROR(VLOOKUP(B9,טבלאות!$G:$H,2,0)),"",VLOOKUP(B9,טבלאות!$G:$H,2,0)) -> רכב ותחבורה | M9: =IF(OR(L9="",L9="?"),"",IF(L9>0,I9,"")) -> 145.52
A10: ויזה 7520 | B10: סיאם סנטר | C10: 26/02/2026 | D10: 40 | E10: כאל | F10: ישראל | H10: 02/03/2026 | I10: 40 | K10: =IF(A10>0,VLOOKUP(A10,טבלאות!$J:$K,2,0),"") -> אשראי מיכה | L10: =IF(ISERROR(VLOOKUP(B10,טבלאות!$G:$H,2,0)),"",VLOOKUP(B10,טבלאות!$G:$H,2,0)) -> ביגוד והנעלה | M10: =IF(OR(L10="",L10="?"),"",IF(L10>0,I10,"")) -> 40
A11: ויזה 7520 | B11: סנטר 1 שערי ירושלים בעמ | C11: 26/02/2026 | D11: 90 | E11: כאל | F11: ישראל | H11: 02/03/2026 | I11: 90 | K11: =IF(A11>0,VLOOKUP(A11,טבלאות!$J:$K,2,0),"") -> אשראי מיכה | L11: =IF(ISERROR(VLOOKUP(B11,טבלאות!$G:$H,2,0)),"",VLOOKUP(B11,טבלאות!$G:$H,2,0)) -> רכב ותחבורה | M11: =IF(OR(L11="",L11="?"),"",IF(L11>0,I11,"")) -> 90
A12: ויזה 3669 | B12: העברה ב BIT בנה"פ | C12: 26/02/2026 | D12: 130 | E12: כאל | F12: ישראל | G12: העברה לשרית קרת | H12: 02/03/2026 | I12: 130 | K12: =IF(A12>0,VLOOKUP(A12,טבלאות!$J:$K,2,0),"") -> אשראי אורנה | L12: =IF(ISERROR(VLOOKUP(B12,טבלאות!$G:$H,2,0)),"",VLOOKUP(B12,טבלאות!$G:$H,2,0)) -> חוגים | M12: =IF(OR(L12="",L12="?"),"",IF(L12>0,I12,"")) -> 130
A13: ויזה 3669 | B13: הראל ביטוח חיים | C13: 26/02/2026 | D13: 56.76 | E13: כאל | F13: ישראל | G13: הוראת קבע | H13: 02/03/2026 | I13: 56.76 | K13: =IF(A13>0,VLOOKUP(A13,טבלאות!$J:$K,2,0),"") -> אשראי אורנה | L13: =IF(ISERROR(VLOOKUP(B13,טבלאות!$G:$H,2,0)),"",VLOOKUP(B13,טבלאות!$G:$H,2,0)) -> ביטוח | M13: =IF(OR(L13="",L13="?"),"",IF(L13>0,I13,"")) -> 56.76
A14: ויזה 7520 | B14: גולן טלקום | C14: 25/02/2026 | D14: 138.47 | E14: כאל | F14: ישראל | G14: הוראת קבע | H14: 02/03/2026 | I14: 138.47 | K14: =IF(A14>0,VLOOKUP(A14,טבלאות!$J:$K,2,0),"") -> אשראי מיכה | L14: =IF(ISERROR(VLOOKUP(B14,טבלאות!$G:$H,2,0)),"",VLOOKUP(B14,טבלאות!$G:$H,2,0)) -> מוצרי חשמל ותקשורת | M14: =IF(OR(L14="",L14="?"),"",IF(L14>0,I14,"")) -> 138.47
A15: ויזה 7520 | B15: כלל ביטוח חיים הו"ק | C15: 25/02/2026 | D15: 79.77 | E15: כאל | F15: ישראל | G15: הוראת קבע | H15: 02/03/2026 | I15: 79.77 | K15: =IF(A15>0,VLOOKUP(A15,טבלאות!$J:$K,2,0),"") -> אשראי מיכה | L15: =IF(ISERROR(VLOOKUP(B15,טבלאות!$G:$H,2,0)),"",VLOOKUP(B15,טבלאות!$G:$H,2,0)) -> ביטוח | M15: =IF(OR(L15="",L15="?"),"",IF(L15>0,I15,"")) -> 79.77
A16: ויזה 3669 | B16: דלק מנטה קמעונאות דרכים ב | C16: 25/02/2026 | D16: 220.93 | E16: כאל | F16: ישראל | H16: 02/03/2026 | I16: 220.93 | K16: =IF(A16>0,VLOOKUP(A16,טבלאות!$J:$K,2,0),"") -> אשראי אורנה | L16: =IF(ISERROR(VLOOKUP(B16,טבלאות!$G:$H,2,0)),"",VLOOKUP(B16,טבלאות!$G:$H,2,0)) -> רכב ותחבורה | M16: =IF(OR(L16="",L16="?"),"",IF(L16>0,I16,"")) -> 220.93
A17: ויזה 7520 | B17: סופר פארם ישפרו - נס ציונ | C17: 24/02/2026 | D17: 75.9 | E17: כאל | F17: ישראל | H17: 02/03/2026 | I17: 75.9 | K17: =IF(A17>0,VLOOKUP(A17,טבלאות!$J:$K,2,0),"") -> אשראי מיכה | L17: =IF(ISERROR(VLOOKUP(B17,טבלאות!$G:$H,2,0)),"",VLOOKUP(B17,טבלאות!$G:$H,2,0)) -> בריאות | M17: =IF(OR(L17="",L17="?"),"",IF(L17>0,I17,"")) -> 75.9
A18: ויזה 7520 | B18: גליקסמן שיווק ביצים | C18: 24/02/2026 | D18: 79 | E18: כאל | F18: ישראל | H18: 02/03/2026 | I18: 79 | K18: =IF(A18>0,VLOOKUP(A18,טבלאות!$J:$K,2,0),"") -> אשראי מיכה | L18: =IF(ISERROR(VLOOKUP(B18,טבלאות!$G:$H,2,0)),"",VLOOKUP(B18,טבלאות!$G:$H,2,0)) -> מזון ומשקאות | M18: =IF(OR(L18="",L18="?"),"",IF(L18>0,I18,"")) -> 79
A19: ויזה 7520 | B19: מ. יוחננוף ובניו- רחובות | C19: 24/02/2026 | D19: 831.85 | E19: כאל | F19: ישראל | H19: 02/03/2026 | I19: 831.85 | K19: =IF(A19>0,VLOOKUP(A19,טבלאות!$J:$K,2,0),"") -> אשראי מיכה | L19: =IF(ISERROR(VLOOKUP(B19,טבלאות!$G:$H,2,0)),"",VLOOKUP(B19,טבלאות!$G:$H,2,0)) -> מזון ומשקאות | M19: =IF(OR(L19="",L19="?"),"",IF(L19>0,I19,"")) -> 831.85
A20: ויזה 3669 | B20: קואופ רחובות | C20: 24/02/2026 | D20: 143.31 | E20: כאל | F20: ישראל | H20: 02/03/2026 | I20: 143.31 | K20: =IF(A20>0,VLOOKUP(A20,טבלאות!$J:$K,2,0),"") -> אשראי אורנה | L20: =IF(ISERROR(VLOOKUP(B20,טבלאות!$G:$H,2,0)),"",VLOOKUP(B20,טבלאות!$G:$H,2,0)) -> מזון ומשקאות | M20: =IF(OR(L20="",L20="?"),"",IF(L20>0,I20,"")) -> 143.31
A21: ויזה 3669 | B21: העברה ב BIT בנה"פ | C21: 24/02/2026 | D21: 100 | E21: כאל | F21: ישראל | G21: העברה למרשה דוידוביץ | H21: 02/03/2026 | I21: 100 | K21: =IF(A21>0,VLOOKUP(A21,טבלאות!$J:$K,2,0),"") -> אשראי אורנה | L21: =IF(ISERROR(VLOOKUP(B21,טבלאות!$G:$H,2,0)),"",VLOOKUP(B21,טבלאות!$G:$H,2,0)) -> חוגים | M21: =IF(OR(L21="",L21="?"),"",IF(L21>0,I21,"")) -> 100
A22: ויזה 3669 | B22: העברה ב BIT בנה"פ | C22: 24/02/2026 | D22: 130 | E22: כאל | F22: ישראל | G22: העברה לשרית קרת | H22: 02/03/2026 | I22: 130 | K22: =IF(A22>0,VLOOKUP(A22,טבלאות!$J:$K,2,0),"") -> אשראי אורנה | L22: =IF(ISERROR(VLOOKUP(B22,טבלאות!$G:$H,2,0)),"",VLOOKUP(B22,טבלאות!$G:$H,2,0)) -> חוגים | M22: =IF(OR(L22="",L22="?"),"",IF(L22>0,I22,"")) -> 130
A23: ויזה 3669 | B23: קואופ רחובות | C23: 24/02/2026 | D23: 15.9 | E23: כאל | F23: ישראל | H23: 02/03/2026 | I23: 15.9 | K23: =IF(A23>0,VLOOKUP(A23,טבלאות!$J:$K,2,0),"") -> אשראי אורנה | L23: =IF(ISERROR(VLOOKUP(B23,טבלאות!$G:$H,2,0)),"",VLOOKUP(B23,טבלאות!$G:$H,2,0)) -> מזון ומשקאות | M23: =IF(OR(L23="",L23="?"),"",IF(L23>0,I23,"")) -> 15.9
A24: ויזה 3669 | B24: אגודת אכסניות נוער בישראל | C24: 24/02/2026 | D24: 395 | E24: כאל | F24: ישראל | H24: 02/03/2026 | I24: 395 | K24: =IF(A24>0,VLOOKUP(A24,טבלאות!$J:$K,2,0),"") -> אשראי אורנה | L24: =IF(ISERROR(VLOOKUP(B24,טבלאות!$G:$H,2,0)),"",VLOOKUP(B24,טבלאות!$G:$H,2,0)) -> ילדים | M24: =IF(OR(L24="",L24="?"),"",IF(L24>0,I24,"")) -> 395
